Workbook

Sheet PF ITARA
B2: Step 1. Decision matrix for each expert | AF2: Step 2. Aggregation | AL2: Step 3. Score values | AT2: Step 4. Normalization | BA2: Step 5. Sorting
AF3: µ values
C4: A1 | D4: A2 | E4: A3 | F4: A4 | G4: A1 | H4: A2 | I4: A3 | J4: A4 | K4: A1 | L4: A2 | M4: A3 | N4: A4 | O4: A1 | P4: A2 | Q4: A3 | R4: A4 | S4: A1 | T4: A2 | U4: A3 | V4: A4 | W4: A1 | X4: A2 | Y4: A3 | Z4: A4 | AA4: A1 | AB4: A2 | AC4: A3 | AD4: A4 | AG4: A1 | AH4: A2 | AI4: A3 | AJ4: A4 | AM4: A1 | AN4: A2 | AO4: A3 | AP4: A4 | AQ4: Aspire | AR4: Sum | AU4: A1 | AV4: A2 | AW4: A3 | AX4: A4 | AY4: Aspire | BA4: {=TRANSPOSE(AT4:AY22)} -> 0 | BB4: C1 | BC4: C2 | BD4: C3 | BE4: C4 | BF4: C5 | BG4: C6 | BH4: C7 | BI4: C8 | BJ4: C9 | BK4: C10 | BL4: C11 | BM4: C12 | BN4: C13 | BO4: C14 | BP4: C15 | BQ4: C16 | BR4: C17 | BS4: C18
B5: C1 | C5: MP | D5: MG | E5: P | F5: MP | G5: MP | H5: F | I5: G | J5: P | K5: F | L5: MG | M5: G | N5: G | O5: P | P5: MG | Q5: MG | R5: P | S5: P | T5: MG | U5: G | V5: VG | W5: G | X5: G | Y5: VG | Z5: MP | AA5: MG | AB5: MP | AC5: G | AD5: F | AF5: C1 | AG5: =SQRT(1-((((1-C27^2))^$C$25)*(((1-G27^2))^$G$25)*(((1-K27^2))^$K$25)*(((1-O27^2))^$O$25)*(((1-S27^2))^$S$25)*(((1-W27^2))^$W$25)*(((1-AA27^2))^$AA$25))) -> 0.4756967 | AH5: =SQRT(1-((((1-D27^2))^$C$25)*(((1-H27^2))^$G$25)*(((1-L27^2))^$K$25)*(((1-P27^2))^$O$25)*(((1-T27^2))^$S$25)*(((1-X27^2))^$W$25)*(((1-AB27^2))^$AA$25))) -> 0.57546269 | AI5: =SQRT(1-((((1-E27^2))^$C$25)*(((1-I27^2))^$G$25)*(((1-M27^2))^$K$25)*(((1-Q27^2))^$O$25)*(((1-U27^2))^$S$25)*(((1-Y27^2))^$W$25)*(((1-AC27^2))^$AA$25))) -> 0.67493137 | AJ5: =SQRT(1-((((1-F27^2))^$C$25)*(((1-J27^2))^$G$25)*(((1-N27^2))^$K$25)*(((1-R27^2))^$O$25)*(((1-V27^2))^$S$25)*(((1-Z27^2))^$W$25)*(((1-AD27^2))^$AA$25))) -> 0.53604023 | AL5: C1 | AM5: =(1+AG5^2-AG27^2)/2 -> 0.40540554 | AN5: =(1+AH5^2-AH27^2)/2 -> 0.52895706 | AO5: =(1+AI5^2-AI27^2)/2 -> 0.64414112 | AP5: =(1+AJ5^2-AJ27^2)/2 -> 0.46414211 | AQ5: 1 | AR5: =SUM(AM5:AP5) -> 2.0426458 | AT5: C1 | AU5: =AM5/SUM($AM5:$AP5) -> 0.19847079 | AV5: =AN5/SUM($AM5:$AP5) -> 0.25895682 | AW5: =AO5/SUM($AM5:$AP5) -> 0.31534645 | AX5: =AP5/SUM($AM5:$AP5) -> 0.22722593 | AY5: =AQ5/SUM($AM5:$AP5) -> 0.48956113 | BA5: A1 | BB5: 0.19847079 | BC5: 0.20716832 | BD5: 0.25603584 | BE5: 0.24997105 | BF5: 0.22380877 | BG5: 0.25490939 | BH5: 0.24108697 | BI5: 0.2174704 | BJ5: 0.24675231 | BK5: 0.20445142 | BL5: 0.2415772 | BM5: 0.25277684 | BN5: 0.23940179 | BO5: 0.24123819 | BP5: 0.24455899 | BQ5: 0.26804314 | BR5: 0.2608173 | BS5: 0.2314713
B6: C2 | C6: MP | D6: MG | E6: P | F6: MP | G6: MP | H6: MG | I6: P | J6: MP | K6: F | L6: MG | M6: MG | N6: F | O6: P | P6: MG | Q6: MG | R6: P | S6: VP | T6: G | U6: MG | V6: MP | W6: MP | X6: F | Y6: VG | Z6: MP | AA6: G | AB6: MP | AC6: MG | AD6: F | AF6: C2 | AG6: =SQRT(1-((((1-C28^2))^$C$25)*(((1-G28^2))^$G$25)*(((1-K28^2))^$K$25)*(((1-O28^2))^$O$25)*(((1-S28^2))^$S$25)*(((1-W28^2))^$W$25)*(((1-AA28^2))^$AA$25))) -> 0.42941373 | AH6: =SQRT(1-((((1-D28^2))^$C$25)*(((1-H28^2))^$G$25)*(((1-L28^2))^$K$25)*(((1-P28^2))^$O$25)*(((1-T28^2))^$S$25)*(((1-X28^2))^$W$25)*(((1-AB28^2))^$AA$25))) -> 0.57546269 | AI6: =SQRT(1-((((1-E28^2))^$C$25)*(((1-I28^2))^$G$25)*(((1-M28^2))^$K$25)*(((1-Q28^2))^$O$25)*(((1-U28^2))^$S$25)*(((1-Y28^2))^$W$25)*(((1-AC28^2))^$AA$25))) -> 0.59002938 | AJ6: =SQRT(1-((((1-F28^2))^$C$25)*(((1-J28^2))^$G$25)*(((1-N28^2))^$K$25)*(((1-R28^2))^$O$25)*(((1-V28^2))^$S$25)*(((1-Z28^2))^$W$25)*(((1-AD28^2))^$AA$25))) -> 0.37642405 | AL6: C2 | AM6: =(1+AG6^2-AG28^2)/2 -> 0.35510413 | AN6: =(1+AH6^2-AH28^2)/2 -> 0.52895706 | AO6: =(1+AI6^2-AI28^2)/2 -> 0.52777898 | AP6: =(1+AJ6^2-AJ28^2)/2 -> 0.30224494 | AQ6: 1 | AR6: =SUM(AM6:AP6) -> 1.7140851 | AT6: C2 | AU6: =AM6/SUM($AM6:$AP6) -> 0.20716832 | AV6: =AN6/SUM($AM6:$AP6) -> 0.3085944 | AW6: =AO6/SUM($AM6:$AP6) -> 0.3079071 | AX6: =AP6/SUM($AM6:$AP6) -> 0.17633018 | AY6: =AQ6/SUM($AM6:$AP6) -> 0.5834016 | BA6: A2 | BB6: 0.25895682 | BC6: 0.3085944 | BD6: 0.27385603 | BE6: 0.2652693 | BF6: 0.23682721 | BG6: 0.27460846 | BH6: 0.24801041 | BI6: 0.2355887 | BJ6: 0.26582101 | BK6: 0.29181491 | BL6: 0.21044073 | BM6: 0.24794955 | BN6: 0.28041772 | BO6: 0.2738763 | BP6: 0.21491769 | BQ6: 0.23593527 | BR6: 0.28313114 | BS6: 0.21745697
B7: C3 | C7: MP | D7: MG | E7: F | F7: MP | G7: P | H7: F | I7: G | J7: MG | K7: G | L7: MG | M7: F | N7: G | O7: P | P7: MG | Q7: MG | R7: P | S7: G | T7: MG | U7: F | V7: VG | W7: G | X7: VG | Y7: MP | Z7: P | AA7: MG | AB7: F | AC7: P | AD7: MG | AF7: C3 | AG7: =SQRT(1-((((1-C29^2))^$C$25)*(((1-G29^2))^$G$25)*(((1-K29^2))^$K$25)*(((1-O29^2))^$O$25)*(((1-S29^2))^$S$25)*(((1-W29^2))^$W$25)*(((1-AA29^2))^$AA$25))) -> 0.57297605 | AH7: =SQRT(1-((((1-D29^2))^$C$25)*(((1-H29^2))^$G$25)*(((1-L29^2))^$K$25)*(((1-P29^2))^$O$25)*(((1-T29^2))^$S$25)*(((1-X29^2))^$W$25)*(((1-AB29^2))^$AA$25))) -> 0.61012688 | AI7: =SQRT(1-((((1-E29^2))^$C$25)*(((1-I29^2))^$G$25)*(((1-M29^2))^$K$25)*(((1-Q29^2))^$O$25)*(((1-U29^2))^$S$25)*(((1-Y29^2))^$W$25)*(((1-AC29^2))^$AA$25))) -> 0.50103391 | AJ7: =SQRT(1-((((1-F29^2))^$C$25)*(((1-J29^2))^$G$25)*(((1-N29^2))^$K$25)*(((1-R29^2))^$O$25)*(((1-V29^2))^$S$25)*(((1-Z29^2))^$W$25)*(((1-AD29^2))^$AA$25))) -> 0.58295461 | AL7: C3 | AM7: =(1+AG7^2-AG29^2)/2 -> 0.52414892 | AN7: =(1+AH7^2-AH29^2)/2 -> 0.56062988 | AO7: =(1+AI7^2-AI29^2)/2 -> 0.44081516 | AP7: =(1+AJ7^2-AJ29^2)/2 -> 0.52157614 | AQ7: 1 | AR7: =SUM(AM7:AP7) -> 2.0471701 | AT7: C3 | AU7: =AM7/SUM($AM7:$AP7) -> 0.25603584 | AV7: =AN7/SUM($AM7:$AP7) -> 0.27385603 | AW7: =AO7/SUM($AM7:$AP7) -> 0.21532903 | AX7: =AP7/SUM($AM7:$AP7) -> 0.25477909 | AY7: =AQ7/SUM($AM7:$AP7) -> 0.48847919 | BA7: A3 | BB7: 0.31534645 | BC7: 0.3079071 | BD7: 0.21532903 | BE7: 0.25108002 | BF7: 0.29602153 | BG7: 0.23060038 | BH7: 0.22329699 | BI7: 0.2435036 | BJ7: 0.22322118 | BK7: 0.23873247 | BL7: 0.30640486 | BM7: 0.2526302 | BN7: 0.24887836 | BO7: 0.21612074 | BP7: 0.32384192 | BQ7: 0.2837421 | BR7: 0.22982563 | BS7: 0.27261901
B8: C4 | C8: G | D8: MG | E8: G | F8: G | G8: MG | H8: F | I8: G | J8: MP | K8: MG | L8: G | M8: MG | N8: F | O8: G | P8: G | Q8: G | R8: G | S8: MG | T8: G | U8: MG | V8: F | W8: MG | X8: G | Y8: G | Z8: MG | AA8: G | AB8: VG | AC8: F | AD8: VG | AF8: C4 | AG8: =SQRT(1-((((1-C30^2))^$C$25)*(((1-G30^2))^$G$25)*(((1-K30^2))^$K$25)*(((1-O30^2))^$O$25)*(((1-S30^2))^$S$25)*(((1-W30^2))^$W$25)*(((1-AA30^2))^$AA$25))) -> 0.64756805 | AH8: =SQRT(1-((((1-D30^2))^$C$25)*(((1-H30^2))^$G$25)*(((1-L30^2))^$K$25)*(((1-P30^2))^$O$25)*(((1-T30^2))^$S$25)*(((1-X30^2))^$W$25)*(((1-AB30^2))^$AA$25))) -> 0.68242246 | AI8: =SQRT(1-((((1-E30^2))^$C$25)*(((1-I30^2))^$G$25)*(((1-M30^2))^$K$25)*(((1-Q30^2))^$O$25)*(((1-U30^2))^$S$25)*(((1-Y30^2))^$W$25)*(((1-AC30^2))^$AA$25))) -> 0.64801881 | AJ8: =SQRT(1-((((1-F30^2))^$C$25)*(((1-J30^2))^$G$25)*(((1-N30^2))^$K$25)*(((1-R30^2))^$O$25)*(((1-V30^2))^$S$25)*(((1-Z30^2))^$W$25)*(((1-AD30^2))^$AA$25))) -> 0.62012391 | AL8: C4 | AM8: =(1+AG8^2-AG30^2)/2 -> 0.61759821 | AN8: =(1+AH8^2-AH30^2)/2 -> 0.65539527 | AO8: =(1+AI8^2-AI30^2)/2 -> 0.6203381 | AP8: =(1+AJ8^2-AJ30^2)/2 -> 0.57734733 | AQ8: 1 | AR8: =SUM(AM8:AP8) -> 2.4706789 | AT8: C4 | AU8: =AM8/SUM($AM8:$AP8) -> 0.24997105 | AV8: =AN8/SUM($AM8:$AP8) -> 0.2652693 | AW8: =AO8/SUM($AM8:$AP8) -> 0.25108002 | AX8: =AP8/SUM($AM8:$AP8) -> 0.23367963 | AY8: =AQ8/SUM($AM8:$AP8) -> 0.40474705 | BA8: A4 | BB8: 0.22722593 | BC8: 0.17633018 | BD8: 0.25477909 | BE8: 0.23367963 | BF8: 0.24334248 | BG8: 0.23988178 | BH8: 0.28760563 | BI8: 0.3034373 | BJ8: 0.2642055 | BK8: 0.2650012 | BL8: 0.2415772 | BM8: 0.24664341 | BN8: 0.23130213 | BO8: 0.26876477 | BP8: 0.2166814 | BQ8: 0.21227948 | BR8: 0.22622593 | BS8: 0.27845272
B9: C5 | C9: MP | D9: MG | E9: G | F9: MP | G9: G | H9: MG | I9: MP | J9: G | K9: MP | L9: MG | M9: G | N9: F | O9: G | P9: G | Q9: G | R9: G | S9: MP | T9: MG | U9: G | V9: MG | W9: F | X9: MP | Y9: G | Z9: MG | AA9: MG | AB9: MP | AC9: G | AD9: F | AF9: C5 | AG9: =SQRT(1-((((1-C31^2))^$C$25)*(((1-G31^2))^$G$25)*(((1-K31^2))^$K$25)*(((1-O31^2))^$O$25)*(((1-S31^2))^$S$25)*(((1-W31^2))^$W$25)*(((1-AA31^2))^$AA$25))) -> 0.53981816 | AH9: =SQRT(1-((((1-D31^2))^$C$25)*(((1-H31^2))^$G$25)*(((1-L31^2))^$K$25)*(((1-P31^2))^$O$25)*(((1-T31^2))^$S$25)*(((1-X31^2))^$W$25)*(((1-AB31^2))^$AA$25))) -> 0.56741576 | AI9: =SQRT(1-((((1-E31^2))^$C$25)*(((1-I31^2))^$G$25)*(((1-M31^2))^$K$25)*(((1-Q31^2))^$O$25)*(((1-U31^2))^$S$25)*(((1-Y31^2))^$W$25)*(((1-AC31^2))^$AA$25))) -> 0.66999252 | AJ9: =SQRT(1-((((1-F31^2))^$C$25)*(((1-J31^2))^$G$25)*(((1-N31^2))^$K$25)*(((1-R31^2))^$O$25)*(((1-V31^2))^$S$25)*(((1-Z31^2))^$W$25)*(((1-AD31^2))^$AA$25))) -> 0.57604687 | AL9: C5 | AM9: =(1+AG9^2-AG31^2)/2 -> 0.49014638 | AN9: =(1+AH9^2-AH31^2)/2 -> 0.51865706 | AO9: =(1+AI9^2-AI31^2)/2 -> 0.64829399 | AP9: =(1+AJ9^2-AJ31^2)/2 -> 0.53292564 | AQ9: 1 | AR9: =SUM(AM9:AP9) -> 2.1900231 | AT9: C5 | AU9: =AM9/SUM($AM9:$AP9) -> 0.22380877 | AV9: =AN9/SUM($AM9:$AP9) -> 0.23682721 | AW9: =AO9/SUM($AM9:$AP9) -> 0.29602153 | AX9: =AP9/SUM($AM9:$AP9) -> 0.24334248 | AY9: =AQ9/SUM($AM9:$AP9) -> 0.45661619 | BA9: Aspire | BB9: 0.48956113 | BC9: 0.5834016 | BD9: 0.48847919 | BE9: 0.40474705 | BF9: 0.45661619 | BG9: 0.40093637 | BH9: 0.38244323 | BI9: 0.40349537 | BJ9: 0.38810643 | BK9: 0.39452306 | BL9: 0.42969859 | BM9: 0.39602919 | BN9: 0.4242591 | BO9: 0.37658352 | BP9: 0.45375565 | BQ9: 0.43754311 | BR9: 0.38961686 | BS9: 0.4159612
B10: C6 | C10: G | D10: MG | E10: G | F10: VG | G10: MG | H10: G | I10: MG | J10: F | K10: MG | L10: G | M10: MG | N10: F | O10: G | P10: G | Q10: G | R10: G | S10: MG | T10: VG | U10: G | V10: MP | W10: G | X10: MG | Y10: MP | Z10: G | AA10: G | AB10: VG | AC10: F | AD10: G | AF10: C6 | AG10: =SQRT(1-((((1-C32^2))^$C$25)*(((1-G32^2))^$G$25)*(((1-K32^2))^$K$25)*(((1-O32^2))^$O$25)*(((1-S32^2))^$S$25)*(((1-W32^2))^$W$25)*(((1-AA32^2))^$AA$25))) -> 0.66172259 | AH10: =SQRT(1-((((1-D32^2))^$C$25)*(((1-H32^2))^$G$25)*(((1-L32^2))^$K$25)*(((1-P32^2))^$O$25)*(((1-T32^2))^$S$25)*(((1-X32^2))^$W$25)*(((1-AB32^2))^$AA$25))) -> 0.71229574 | AI10: =SQRT(1-((((1-E32^2))^$C$25)*(((1-I32^2))^$G$25)*(((1-M32^2))^$K$25)*(((1-Q32^2))^$O$25)*(((1-U32^2))^$S$25)*(((1-Y32^2))^$W$25)*(((1-AC32^2))^$AA$25))) -> 0.61087644 | AJ10: =SQRT(1-((((1-F32^2))^$C$25)*(((1-J32^2))^$G$25)*(((1-N32^2))^$K$25)*(((1-R32^2))^$O$25)*(((1-V32^2))^$S$25)*(((1-Z32^2))^$W$25)*(((1-AD32^2))^$AA$25))) -> 0.63576447 | AL10: C6 | AM10: =(1+AG10^2-AG32^2)/2 -> 0.63578515 | AN10: =(1+AH10^2-AH32^2)/2 -> 0.68491781 | AO10: =(1+AI10^2-AI32^2)/2 -> 0.57515455 | AP10: =(1+AJ10^2-AJ32^2)/2 -> 0.59830386 | AQ10: 1 | AR10: =SUM(AM10:AP10) -> 2.4941614 | AT10: C6 | AU10: =AM10/SUM($AM10:$AP10) -> 0.25490939 | AV10: =AN10/SUM($AM10:$AP10) -> 0.27460846 | AW10: =AO10/SUM($AM10:$AP10) -> 0.23060038 | AX10: =AP10/SUM($AM10:$AP10) -> 0.23988178 | AY10: =AQ10/SUM($AM10:$AP10) -> 0.40093637
B11: C7 | C11: MG | D11: G | E11: G | F11: VG | G11: MP | H11: MP | I11: F | J11: G | K11: MG | L11: G | M11: MG | N11: G | O11: G | P11: G | Q11: G | R11: VG | S11: VG | T11: MG | U11: G | V11: VG | W11: VG | X11: VG | Y11: MG | Z11: VG | AA11: MG | AB11: G | AC11: F | AD11: VG | AF11: C7 | AG11: =SQRT(1-((((1-C33^2))^$C$25)*(((1-G33^2))^$G$25)*(((1-K33^2))^$K$25)*(((1-O33^2))^$O$25)*(((1-S33^2))^$S$25)*(((1-W33^2))^$W$25)*(((1-AA33^2))^$AA$25))) -> 0.67089813 | AH11: =SQRT(1-((((1-D33^2))^$C$25)*(((1-H33^2))^$G$25)*(((1-L33^2))^$K$25)*(((1-P33^2))^$O$25)*(((1-T33^2))^$S$25)*(((1-X33^2))^$W$25)*(((1-AB33^2))^$AA$25))) -> 0.67701826 | AI11: =SQRT(1-((((1-E33^2))^$C$25)*(((1-I33^2))^$G$25)*(((1-M33^2))^$K$25)*(((1-Q33^2))^$O$25)*(((1-U33^2))^$S$25)*(((1-Y33^2))^$W$25)*(((1-AC33^2))^$AA$25))) -> 0.61779617 | AJ11: =SQRT(1-((((1-F33^2))^$C$25)*(((1-J33^2))^$G$25)*(((1-N33^2))^$K$25)*(((1-R33^2))^$O$25)*(((1-V33^2))^$S$25)*(((1-Z33^2))^$W$25)*(((1-AD33^2))^$AA$25))) -> 0.77609981 | AL11: C7 | AM11: =(1+AG11^2-AG33^2)/2 -> 0.63038629 | AN11: =(1+AH11^2-AH33^2)/2 -> 0.64848948 | AO11: =(1+AI11^2-AI33^2)/2 -> 0.58386965 | AP11: =(1+AJ11^2-AJ33^2)/2 -> 0.75202176 | AQ11: 1 | AR11: =SUM(AM11:AP11) -> 2.6147672 | AT11: C7 | AU11: =AM11/SUM($AM11:$AP11) -> 0.24108697 | AV11: =AN11/SUM($AM11:$AP11) -> 0.24801041 | AW11: =AO11/SUM($AM11:$AP11) -> 0.22329699 | AX11: =AP11/SUM($AM11:$AP11) -> 0.28760563 | AY11: =AQ11/SUM($AM11:$AP11) -> 0.38244323 | BB11: C1 | BC11: C2 | BD11: C3 | BE11: C4 | BF11: C5 | BG11: C6 | BH11: C7 | BI11: C8 | BJ11: C9 | BK11: C10 | BL11: C11 | BM11: C12 | BN11: C13 | BO11: C14 | BP11: C15 | BQ11: C16 | BR11: C17 | BS11: C18
B12: C8 | C12: MG | D12: G | E12: G | F12: VG | G12: F | H12: F | I12: F | J12: G | K12: MG | L12: MG | M12: G | N12: G | O12: MG | P12: MG | Q12: MG | R12: VG | S12: MG | T12: G | U12: VG | V12: VG | W12: G | X12: G | Y12: F | Z12: VG | AA12: F | AB12: F | AC12: MG | AD12: VG | AF12: C8 | AG12: =SQRT(1-((((1-C34^2))^$C$25)*(((1-G34^2))^$G$25)*(((1-K34^2))^$K$25)*(((1-O34^2))^$O$25)*(((1-S34^2))^$S$25)*(((1-W34^2))^$W$25)*(((1-AA34^2))^$AA$25))) -> 0.58329173 | AH12: =SQRT(1-((((1-D34^2))^$C$25)*(((1-H34^2))^$G$25)*(((1-L34^2))^$K$25)*(((1-P34^2))^$O$25)*(((1-T34^2))^$S$25)*(((1-X34^2))^$W$25)*(((1-AB34^2))^$AA$25))) -> 0.61779617 | AI12: =SQRT(1-((((1-E34^2))^$C$25)*(((1-I34^2))^$G$25)*(((1-M34^2))^$K$25)*(((1-Q34^2))^$O$25)*(((1-U34^2))^$S$25)*(((1-Y34^2))^$W$25)*(((1-AC34^2))^$AA$25))) -> 0.64162763 | AJ12: =SQRT(1-((((1-F34^2))^$C$25)*(((1-J34^2))^$G$25)*(((1-N34^2))^$K$25)*(((1-R34^2))^$O$25)*(((1-V34^2))^$S$25)*(((1-Z34^2))^$W$25)*(((1-AD34^2))^$AA$25))) -> 0.77609981 | AL12: C8 | AM12: =(1+AG12^2-AG34^2)/2 -> 0.53896628 | AN12: =(1+AH12^2-AH34^2)/2 -> 0.58386965 | AO12: =(1+AI12^2-AI34^2)/2 -> 0.60348549 | AP12: =(1+AJ12^2-AJ34^2)/2 -> 0.75202176 | AQ12: 1 | AR12: =SUM(AM12:AP12) -> 2.4783432 | AT12: C8 | AU12: =AM12/SUM($AM12:$AP12) -> 0.2174704 | AV12: =AN12/SUM($AM12:$AP12) -> 0.2355887 | AW12: =AO12/SUM($AM12:$AP12) -> 0.2435036 | AX12: =AP12/SUM($AM12:$AP12) -> 0.3034373 | AY12: =AQ12/SUM($AM12:$AP12) -> 0.40349537 | BB12: {=_xlfn._xlws.SORT(BB5:BB9)} -> 0.19847079 | BC12: {=_xlfn._xlws.SORT(BC5:BC9)} -> 0.17633018 | BD12: {=_xlfn._xlws.SORT(BD5:BD9)} -> 0.21532903 | BE12: {=_xlfn._xlws.SORT(BE5:BE9)} -> 0.23367963 | BF12: {=_xlfn._xlws.SORT(BF5:BF9)} -> 0.22380877 | BG12: {=_xlfn._xlws.SORT(BG5:BG9)} -> 0.23060038 | BH12: {=_xlfn._xlws.SORT(BH5:BH9)} -> 0.22329699 | BI12: {=_xlfn._xlws.SORT(BI5:BI9)} -> 0.2174704 | ... BS12: {=_xlfn._xlws.SORT(BS5:BS9)} -> 0.21745697
B13: C9 | C13: G | D13: G | E13: MG | F13: VG | G13: MG | H13: G | I13: G | J13: MP | K13: MG | L13: G | M13: F | N13: MG | O13: MG | P13: MG | Q13: G | R13: VG | S13: G | T13: VG | U13: MG | V13: MG | W13: G | X13: MG | Y13: G | Z13: VG | AA13: G | AB13: VG | AC13: MP | AD13: VG | AF13: C9 | AG13: =SQRT(1-((((1-C35^2))^$C$25)*(((1-G35^2))^$G$25)*(((1-K35^2))^$K$25)*(((1-O35^2))^$O$25)*(((1-S35^2))^$S$25)*(((1-W35^2))^$W$25)*(((1-AA35^2))^$AA$25))) -> 0.66172259 | AH13: =SQRT(1-((((1-D35^2))^$C$25)*(((1-H35^2))^$G$25)*(((1-L35^2))^$K$25)*(((1-P35^2))^$O$25)*(((1-T35^2))^$S$25)*(((1-X35^2))^$W$25)*(((1-AB35^2))^$AA$25))) -> 0.71229574 | AI13: =SQRT(1-((((1-E35^2))^$C$25)*(((1-I35^2))^$G$25)*(((1-M35^2))^$K$25)*(((1-Q35^2))^$O$25)*(((1-U35^2))^$S$25)*(((1-Y35^2))^$W$25)*(((1-AC35^2))^$AA$25))) -> 0.61087644 | AJ13: =SQRT(1-((((1-F35^2))^$C$25)*(((1-J35^2))^$G$25)*(((1-N35^2))^$K$25)*(((1-R35^2))^$O$25)*(((1-V35^2))^$S$25)*(((1-Z35^2))^$W$25)*(((1-AD35^2))^$AA$25))) -> 0.71977858 | AL13: C9 | AM13: =(1+AG13^2-AG35^2)/2 -> 0.63578515 | AN13: =(1+AH13^2-AH35^2)/2 -> 0.68491781 | AO13: =(1+AI13^2-AI35^2)/2 -> 0.57515455 | AP13: =(1+AJ13^2-AJ35^2)/2 -> 0.68075527 | AQ13: 1 | AR13: =SUM(AM13:AP13) -> 2.5766128 | AT13: C9 | AU13: =AM13/SUM($AM13:$AP13) -> 0.24675231 | AV13: =AN13/SUM($AM13:$AP13) -> 0.26582101 | AW13: =AO13/SUM($AM13:$AP13) -> 0.22322118 | AX13: =AP13/SUM($AM13:$AP13) -> 0.2642055 | AY13: =AQ13/SUM($AM13:$AP13) -> 0.38810643 | BB13: 0.22722593 | BC13: 0.20716832 | BD13: 0.25477909 | BE13: 0.24997105 | BF13: 0.23682721 | BG13: 0.23988178 | BH13: 0.24108697 | BI13: 0.2355887 | BJ13: 0.24675231 | BK13: 0.23873247 | BL13: 0.2415772 | BM13: 0.24794955 | BN13: 0.23940179 | BO13: 0.24123819 | BP13: 0.2166814 | BQ13: 0.23593527 | BR13: 0.22982563 | BS13: 0.2314713
B14: C10 | C14: MG | D14: G | E14: MG | F14: G | G14: F | H14: VG | I14: G | J14: F | K14: MG | L14: G | M14: F | N14: MG | O14: F | P14: G | Q14: VG | R14: VG | S14: F | T14: VG | U14: VP | V14: G | W14: MG | X14: VG | Y14: VG | Z14: G | AA14: G | AB14: VG | AC14: MG | AD14: VG | AF14: C10 | AG14: =SQRT(1-((((1-C36^2))^$C$25)*(((1-G36^2))^$G$25)*(((1-K36^2))^$K$25)*(((1-O36^2))^$O$25)*(((1-S36^2))^$S$25)*(((1-W36^2))^$W$25)*(((1-AA36^2))^$AA$25))) -> 0.5649451 | AH14: =SQRT(1-((((1-D36^2))^$C$25)*(((1-H36^2))^$G$25)*(((1-L36^2))^$K$25)*(((1-P36^2))^$O$25)*(((1-T36^2))^$S$25)*(((1-X36^2))^$W$25)*(((1-AB36^2))^$AA$25))) -> 0.76291749 | AI14: =SQRT(1-((((1-E36^2))^$C$25)*(((1-I36^2))^$G$25)*(((1-M36^2))^$K$25)*(((1-Q36^2))^$O$25)*(((1-U36^2))^$S$25)*(((1-Y36^2))^$W$25)*(((1-AC36^2))^$AA$25))) -> 0.65208525 | AJ14: =SQRT(1-((((1-F36^2))^$C$25)*(((1-J36^2))^$G$25)*(((1-N36^2))^$K$25)*(((1-R36^2))^$O$25)*(((1-V36^2))^$S$25)*(((1-Z36^2))^$W$25)*(((1-AD36^2))^$AA$25))) -> 0.70116728 | AL14: C10 | AM14: =(1+AG14^2-AG36^2)/2 -> 0.51822425 | AN14: =(1+AH14^2-AH36^2)/2 -> 0.73966504 | AO14: =(1+AI14^2-AI36^2)/2 -> 0.60511665 | AP14: =(1+AJ14^2-AJ36^2)/2 -> 0.67170016 | AQ14: 1 | AR14: =SUM(AM14:AP14) -> 2.5347061 | AT14: C10 | AU14: =AM14/SUM($AM14:$AP14) -> 0.20445142 | AV14: =AN14/SUM($AM14:$AP14) -> 0.29181491 | AW14: =AO14/SUM($AM14:$AP14) -> 0.23873247 | AX14: =AP14/SUM($AM14:$AP14) -> 0.2650012 | AY14: =AQ14/SUM($AM14:$AP14) -> 0.39452306 | BB14: 0.25895682 | BC14: 0.3079071 | BD14: 0.25603584 | BE14: 0.25108002 | BF14: 0.24334248 | BG14: 0.25490939 | BH14: 0.24801041 | BI14: 0.2435036 | BJ14: 0.2642055 | BK14: 0.2650012 | BL14: 0.2415772 | BM14: 0.2526302 | BN14: 0.24887836 | BO14: 0.26876477 | BP14: 0.24455899 | BQ14: 0.26804314 | BR14: 0.2608173 | BS14: 0.27261901
B15: C11 | C15: G | D15: G | E15: G | F15: G | G15: MG | H15: F | I15: VG | J15: MG | K15: F | L15: F | M15: G | N15: MG | O15: G | P15: G | Q15: G | R15: G | S15: F | T15: F | U15: G | V15: MG | W15: MG | X15: F | Y15: G | Z15: F | AA15: MG | AB15: MP | AC15: VG | AD15: F | AF15: C11 | AG15: =SQRT(1-((((1-C37^2))^$C$25)*(((1-G37^2))^$G$25)*(((1-K37^2))^$K$25)*(((1-O37^2))^$O$25)*(((1-S37^2))^$S$25)*(((1-W37^2))^$W$25)*(((1-AA37^2))^$AA$25))) -> 0.6010713 | AH15: =SQRT(1-((((1-D37^2))^$C$25)*(((1-H37^2))^$G$25)*(((1-L37^2))^$K$25)*(((1-P37^2))^$O$25)*(((1-T37^2))^$S$25)*(((1-X37^2))^$W$25)*(((1-AB37^2))^$AA$25))) -> 0.53710324 | AI15: =SQRT(1-((((1-E37^2))^$C$25)*(((1-I37^2))^$G$25)*(((1-M37^2))^$K$25)*(((1-Q37^2))^$O$25)*(((1-U37^2))^$S$25)*(((1-Y37^2))^$W$25)*(((1-AC37^2))^$AA$25))) -> 0.73369585 | AJ15: =SQRT(1-((((1-F37^2))^$C$25)*(((1-J37^2))^$G$25)*(((1-N37^2))^$K$25)*(((1-R37^2))^$O$25)*(((1-V37^2))^$S$25)*(((1-Z37^2))^$W$25)*(((1-AD37^2))^$AA$25))) -> 0.6010713 | AL15: C11 | AM15: =(1+AG15^2-AG37^2)/2 -> 0.56220153 | AN15: =(1+AH15^2-AH37^2)/2 -> 0.48974034 | AO15: =(1+AI15^2-AI37^2)/2 -> 0.71306928 | AP15: =(1+AJ15^2-AJ37^2)/2 -> 0.56220153 | AQ15: 1 | AR15: =SUM(AM15:AP15) -> 2.3272127 | AT15: C11 | AU15: =AM15/SUM($AM15:$AP15) -> 0.2415772 | AV15: =AN15/SUM($AM15:$AP15) -> 0.21044073 | AW15: =AO15/SUM($AM15:$AP15) -> 0.30640486 | AX15: =AP15/SUM($AM15:$AP15) -> 0.2415772 | AY15: =AQ15/SUM($AM15:$AP15) -> 0.42969859 | BB15: 0.31534645 | BC15: 0.3085944 | BD15: 0.27385603 | BE15: 0.2652693 | BF15: 0.29602153 | BG15: 0.27460846 | BH15: 0.28760563 | BI15: 0.3034373 | BJ15: 0.26582101 | BK15: 0.29181491 | BL15: 0.30640486 | BM15: 0.25277684 | BN15: 0.28041772 | BO15: 0.2738763 | BP15: 0.32384192 | BQ15: 0.2837421 | BR15: 0.28313114 | BS15: 0.27845272
B16: C12 | C16: MG | D16: VG | E16: MG | F16: VG | G16: F | H16: MP | I16: F | J16: G | K16: MG | L16: G | M16: MG | N16: F | O16: G | P16: G | Q16: G | R16: G | S16: G | T16: G | U16: VG | V16: MG | W16: VG | X16: G | Y16: VG | Z16: F | AA16: G | AB16: MP | AC16: MG | AD16: G | AF16: C12 | AG16: =SQRT(1-((((1-C38^2))^$C$25)*(((1-G38^2))^$G$25)*(((1-K38^2))^$K$25)*(((1-O38^2))^$O$25)*(((1-S38^2))^$S$25)*(((1-W38^2))^$W$25)*(((1-AA38^2))^$AA$25))) -> 0.66939175 | AH16: =SQRT(1-((((1-D38^2))^$C$25)*(((1-H38^2))^$G$25)*(((1-L38^2))^$K$25)*(((1-P38^2))^$O$25)*(((1-T38^2))^$S$25)*(((1-X38^2))^$W$25)*(((1-AB38^2))^$AA$25))) -> 0.6583112 | AI16: =SQRT(1-((((1-E38^2))^$C$25)*(((1-I38^2))^$G$25)*(((1-M38^2))^$K$25)*(((1-Q38^2))^$O$25)*(((1-U38^2))^$S$25)*(((1-Y38^2))^$W$25)*(((1-AC38^2))^$AA$25))) -> 0.67643395 | AJ16: =SQRT(1-((((1-F38^2))^$C$25)*(((1-J38^2))^$G$25)*(((1-N38^2))^$K$25)*(((1-R38^2))^$O$25)*(((1-V38^2))^$S$25)*(((1-Z38^2))^$W$25)*(((1-AD38^2))^$AA$25))) -> 0.65609668 | AL16: C12 | AM16: =(1+AG16^2-AG38^2)/2 -> 0.63827831 | AN16: =(1+AH16^2-AH38^2)/2 -> 0.62608906 | AO16: =(1+AI16^2-AI38^2)/2 -> 0.63790803 | AP16: =(1+AJ16^2-AJ38^2)/2 -> 0.62279098 | AQ16: 1 | AR16: =SUM(AM16:AP16) -> 2.5250664 | AT16: C12 | AU16: =AM16/SUM($AM16:$AP16) -> 0.25277684 | AV16: =AN16/SUM($AM16:$AP16) -> 0.24794955 | AW16: =AO16/SUM($AM16:$AP16) -> 0.2526302 | AX16: =AP16/SUM($AM16:$AP16) -> 0.24664341 | AY16: =AQ16/SUM($AM16:$AP16) -> 0.39602919 | BB16: 0.48956113 | BC16: 0.5834016 | BD16: 0.48847919 | BE16: 0.40474705 | BF16: 0.45661619 | BG16: 0.40093637 | BH16: 0.38244323 | BI16: 0.40349537 | BJ16: 0.38810643 | BK16: 0.39452306 | BL16: 0.42969859 | BM16: 0.39602919 | BN16: 0.4242591 | BO16: 0.37658352 | BP16: 0.45375565 | BQ16: 0.43754311 | BR16: 0.38961686 | BS16: 0.4159612
B17: C13 | C17: MG | D17: G | E17: MG | F17: MG | G17: F | H17: P | I17: G | J17: MG | K17: MG | L17: G | M17: MG | N17: F | O17: F | P17: VG | Q17: VG | R17: VG | S17: F | T17: MG | U17: G | V17: MP | W17: VG | X17: G | Y17: MP | Z17: MP | AA17: G | AB17: VG | AC17: MP | AD17: G | AF17: C13 | AG17: =SQRT(1-((((1-C39^2))^$C$25)*(((1-G39^2))^$G$25)*(((1-K39^2))^$K$25)*(((1-O39^2))^$O$25)*(((1-S39^2))^$S$25)*(((1-W39^2))^$W$25)*(((1-AA39^2))^$AA$25))) -> 0.61064405 | AH17: =SQRT(1-((((1-D39^2))^$C$25)*(((1-H39^2))^$G$25)*(((1-L39^2))^$K$25)*(((1-P39^2))^$O$25)*(((1-T39^2))^$S$25)*(((1-X39^2))^$W$25)*(((1-AB39^2))^$AA$25))) -> 0.69423415 | AI17: =SQRT(1-((((1-E39^2))^$C$25)*(((1-I39^2))^$G$25)*(((1-M39^2))^$K$25)*(((1-Q39^2))^$O$25)*(((1-U39^2))^$S$25)*(((1-Y39^2))^$W$25)*(((1-AC39^2))^$AA$25))) -> 0.62880523 | AJ17: =SQRT(1-((((1-F39^2))^$C$25)*(((1-J39^2))^$G$25)*(((1-N39^2))^$K$25)*(((1-R39^2))^$O$25)*(((1-V39^2))^$S$25)*(((1-Z39^2))^$W$25)*(((1-AD39^2))^$AA$25))) -> 0.5962565 | AL17: C13 | AM17: =(1+AG17^2-AG39^2)/2 -> 0.56428205 | AN17: =(1+AH17^2-AH39^2)/2 -> 0.66095865 | AO17: =(1+AI17^2-AI39^2)/2 -> 0.58661878 | AP17: =(1+AJ17^2-AJ39^2)/2 -> 0.54519075 | AQ17: 1 | AR17: =SUM(AM17:AP17) -> 2.3570502 | AT17: C13 | AU17: =AM17/SUM($AM17:$AP17) -> 0.23940179 | AV17: =AN17/SUM($AM17:$AP17) -> 0.28041772 | AW17: =AO17/SUM($AM17:$AP17) -> 0.24887836 | AX17: =AP17/SUM($AM17:$AP17) -> 0.23130213 | AY17: =AQ17/SUM($AM17:$AP17) -> 0.4242591
B18: C14 | C18: F | D18: MG | E18: MG | F18: MG | G18: MG | H18: G | I18: MP | J18: G | K18: G | L18: VG | M18: MG | N18: G | O18: F | P18: G | Q18: G | R18: VG | S18: VG | T18: VG | U18: VG | V18: VG | W18: VG | X18: VG | Y18: F | Z18: G | AA18: G | AB18: VG | AC18: MG | AD18: VG | AF18: C14 | AG18: =SQRT(1-((((1-C40^2))^$C$25)*(((1-G40^2))^$G$25)*(((1-K40^2))^$K$25)*(((1-O40^2))^$O$25)*(((1-S40^2))^$S$25)*(((1-W40^2))^$W$25)*(((1-AA40^2))^$AA$25))) -> 0.67683708 | AH18: =SQRT(1-((((1-D40^2))^$C$25)*(((1-H40^2))^$G$25)*(((1-L40^2))^$K$25)*(((1-P40^2))^$O$25)*(((1-T40^2))^$S$25)*(((1-X40^2))^$W$25)*(((1-AB40^2))^$AA$25))) -> 0.75383264 | AI18: =SQRT(1-((((1-E40^2))^$C$25)*(((1-I40^2))^$G$25)*(((1-M40^2))^$K$25)*(((1-Q40^2))^$O$25)*(((1-U40^2))^$S$25)*(((1-Y40^2))^$W$25)*(((1-AC40^2))^$AA$25))) -> 0.61962412 | AJ18: =SQRT(1-((((1-F40^2))^$C$25)*(((1-J40^2))^$G$25)*(((1-N40^2))^$K$25)*(((1-R40^2))^$O$25)*(((1-V40^2))^$S$25)*(((1-Z40^2))^$W$25)*(((1-AD40^2))^$AA$25))) -> 0.73907904 | AL18: C14 | AM18: =(1+AG18^2-AG40^2)/2 -> 0.64059678 | AN18: =(1+AH18^2-AH40^2)/2 -> 0.72726576 | AO18: =(1+AI18^2-AI40^2)/2 -> 0.57389854 | AP18: =(1+AJ18^2-AJ40^2)/2 -> 0.71369232 | AQ18: 1 | AR18: =SUM(AM18:AP18) -> 2.6554534 | AT18: C14 | AU18: =AM18/SUM($AM18:$AP18) -> 0.24123819 | AV18: =AN18/SUM($AM18:$AP18) -> 0.2738763 | AW18: =AO18/SUM($AM18:$AP18) -> 0.21612074 | AX18: =AP18/SUM($AM18:$AP18) -> 0.26876477 | AY18: =AQ18/SUM($AM18:$AP18) -> 0.37658352 | BA18: Step 6. Ordered distance differences
B19: C15 | C19: F | D19: G | E19: G | F19: F | G19: MG | H19: MP | I19: VG | J19: MG | K19: MG | L19: F | M19: VG | N19: G | O19: G | P19: MG | Q19: MG | R19: P | S19: F | T19: F | U19: G | V19: MG | W19: MG | X19: MG | Y19: G | Z19: F | AA19: MG | AB19: MP | AC19: VG | AD19: F | AF19: C15 | AG19: =SQRT(1-((((1-C41^2))^$C$25)*(((1-G41^2))^$G$25)*(((1-K41^2))^$K$25)*(((1-O41^2))^$O$25)*(((1-S41^2))^$S$25)*(((1-W41^2))^$W$25)*(((1-AA41^2))^$AA$25))) -> 0.58329173 | AH19: =SQRT(1-((((1-D41^2))^$C$25)*(((1-H41^2))^$G$25)*(((1-L41^2))^$K$25)*(((1-P41^2))^$O$25)*(((1-T41^2))^$S$25)*(((1-X41^2))^$W$25)*(((1-AB41^2))^$AA$25))) -> 0.52722882 | AI19: =SQRT(1-((((1-E41^2))^$C$25)*(((1-I41^2))^$G$25)*(((1-M41^2))^$K$25)*(((1-Q41^2))^$O$25)*(((1-U41^2))^$S$25)*(((1-Y41^2))^$W$25)*(((1-AC41^2))^$AA$25))) -> 0.73907904 | AJ19: =SQRT(1-((((1-F41^2))^$C$25)*(((1-J41^2))^$G$25)*(((1-N41^2))^$K$25)*(((1-R41^2))^$O$25)*(((1-V41^2))^$S$25)*(((1-Z41^2))^$W$25)*(((1-AD41^2))^$AA$25))) -> 0.53296679 | AL19: C15 | AM19: =(1+AG19^2-AG41^2)/2 -> 0.53896628 | AN19: =(1+AH19^2-AH41^2)/2 -> 0.4736419 | AO19: =(1+AI19^2-AI41^2)/2 -> 0.71369232 | AP19: =(1+AJ19^2-AJ41^2)/2 -> 0.47752881 | AQ19: 1 | AR19: =SUM(AM19:AP19) -> 2.2038293 | AT19: C15 | AU19: =AM19/SUM($AM19:$AP19) -> 0.24455899 | AV19: =AN19/SUM($AM19:$AP19) -> 0.21491769 | AW19: =AO19/SUM($AM19:$AP19) -> 0.32384192 | AX19: =AP19/SUM($AM19:$AP19) -> 0.2166814 | AY19: =AQ19/SUM($AM19:$AP19) -> 0.45375565 | BB19: C1 | BC19: C2 | BD19: C3 | BE19: C4 | BF19: C5 | BG19: C6 | BH19: C7 | BI19: C8 | BJ19: C9 | BK19: C10 | BL19: C11 | BM19: C12 | BN19: C13 | BO19: C14 | BP19: C15 | BQ19: C16 | BR19: C17 | BS19: C18
B20: C16 | C20: G | D20: F | E20: G | F20: MG | G20: MP | H20: MP | I20: G | J20: F | K20: MG | L20: G | M20: MG | N20: F | O20: G | P20: G | Q20: G | R20: G | S20: G | T20: VG | U20: G | V20: MP | W20: G | X20: MP | Y20: MP | Z20: MG | AA20: MG | AB20: MP | AC20: VG | AD20: F | AF20: C16 | AG20: =SQRT(1-((((1-C42^2))^$C$25)*(((1-G42^2))^$G$25)*(((1-K42^2))^$K$25)*(((1-O42^2))^$O$25)*(((1-S42^2))^$S$25)*(((1-W42^2))^$W$25)*(((1-AA42^2))^$AA$25))) -> 0.64183512 | AH20: =SQRT(1-((((1-D42^2))^$C$25)*(((1-H42^2))^$G$25)*(((1-L42^2))^$K$25)*(((1-P42^2))^$O$25)*(((1-T42^2))^$S$25)*(((1-X42^2))^$W$25)*(((1-AB42^2))^$AA$25))) -> 0.58933628 | AI20: =SQRT(1-((((1-E42^2))^$C$25)*(((1-I42^2))^$G$25)*(((1-M42^2))^$K$25)*(((1-Q42^2))^$O$25)*(((1-U42^2))^$S$25)*(((1-Y42^2))^$W$25)*(((1-AC42^2))^$AA$25))) -> 0.67701826 | AJ20: =SQRT(1-((((1-F42^2))^$C$25)*(((1-J42^2))^$G$25)*(((1-N42^2))^$K$25)*(((1-R42^2))^$O$25)*(((1-V42^2))^$S$25)*(((1-Z42^2))^$W$25)*(((1-AD42^2))^$AA$25))) -> 0.53643598 | AL20: C16 | AM20: =(1+AG20^2-AG42^2)/2 -> 0.61260968 | AN20: =(1+AH20^2-AH42^2)/2 -> 0.53922749 | AO20: =(1+AI20^2-AI42^2)/2 -> 0.64848948 | AP20: =(1+AJ20^2-AJ42^2)/2 -> 0.48516245 | AQ20: 1 | AR20: =SUM(AM20:AP20) -> 2.2854891 | AT20: C16 | AU20: =AM20/SUM($AM20:$AP20) -> 0.26804314 | AV20: =AN20/SUM($AM20:$AP20) -> 0.23593527 | AW20: =AO20/SUM($AM20:$AP20) -> 0.2837421 | AX20: =AP20/SUM($AM20:$AP20) -> 0.21227948 | AY20: =AQ20/SUM($AM20:$AP20) -> 0.43754311 | BA20: sort 2-1 | BB20: =BB13-BB12 -> 0.028755141 | BC20: =BC13-BC12 -> 0.030838136 | BD20: =BD13-BD12 -> 0.039450057 | BE20: =BE13-BE12 -> 0.016291427 | BF20: =BF13-BF12 -> 0.013018439 | BG20: =BG13-BG12 -> 0.0092813988 | BH20: =BH13-BH12 -> 0.017789975 | BI20: =BI13-BI12 -> 0.018118303 | ... BS20: =BS13-BS12 -> 0.014014336
B21: C17 | C21: MG | D21: G | E21: G | F21: MG | G21: MG | H21: G | I21: MP | J21: MG | K21: MG | L21: VG | M21: F | N21: MG | O21: G | P21: G | Q21: VG | R21: G | S21: VG | T21: VG | U21: G | V21: G | W21: VG | X21: G | Y21: G | Z21: F | AA21: G | AB21: VG | AC21: MP | AD21: MG | AF21: C17 | AG21: =SQRT(1-((((1-C43^2))^$C$25)*(((1-G43^2))^$G$25)*(((1-K43^2))^$K$25)*(((1-O43^2))^$O$25)*(((1-S43^2))^$S$25)*(((1-W43^2))^$W$25)*(((1-AA43^2))^$AA$25))) -> 0.70080222 | AH21: =SQRT(1-((((1-D43^2))^$C$25)*(((1-H43^2))^$G$25)*(((1-L43^2))^$K$25)*(((1-P43^2))^$O$25)*(((1-T43^2))^$S$25)*(((1-X43^2))^$W$25)*(((1-AB43^2))^$AA$25))) -> 0.74881257 | AI21: =SQRT(1-((((1-E43^2))^$C$25)*(((1-I43^2))^$G$25)*(((1-M43^2))^$K$25)*(((1-Q43^2))^$O$25)*(((1-U43^2))^$S$25)*(((1-Y43^2))^$W$25)*(((1-AC43^2))^$AA$25))) -> 0.62928856 | AJ21: =SQRT(1-((((1-F43^2))^$C$25)*(((1-J43^2))^$G$25)*(((1-N43^2))^$K$25)*(((1-R43^2))^$O$25)*(((1-V43^2))^$S$25)*(((1-Z43^2))^$W$25)*(((1-AD43^2))^$AA$25))) -> 0.61729215 | AL21: C17 | AM21: =(1+AG21^2-AG43^2)/2 -> 0.66941994 | AN21: =(1+AH21^2-AH43^2)/2 -> 0.72669118 | AO21: =(1+AI21^2-AI43^2)/2 -> 0.58987599 | AP21: =(1+AJ21^2-AJ43^2)/2 -> 0.58063691 | AQ21: 1 | AR21: =SUM(AM21:AP21) -> 2.566624 | AT21: C17 | AU21: =AM21/SUM($AM21:$AP21) -> 0.2608173 | AV21: =AN21/SUM($AM21:$AP21) -> 0.28313114 | AW21: =AO21/SUM($AM21:$AP21) -> 0.22982563 | AX21: =AP21/SUM($AM21:$AP21) -> 0.22622593 | AY21: =AQ21/SUM($AM21:$AP21) -> 0.38961686 | BA21: sort 3-2 | BB21: =BB14-BB13 -> 0.031730882 | BC21: =BC14-BC13 -> 0.10073879 | BD21: =BD14-BD13 -> 0.0012567524 | BE21: =BE14-BE13 -> 0.0011089607 | BF21: =BF14-BF13 -> 0.0065152663 | BG21: =BG14-BG13 -> 0.015027614 | BH21: =BH14-BH13 -> 0.0069234413 | BI21: =BI14-BI13 -> 0.0079149016 | ... BS21: =BS14-BS13 -> 0.041147702
B22: C18 | C22: MG | D22: MG | E22: G | F22: MG | G22: F | H22: MP | I22: G | J22: G | K22: F | L22: MG | M22: G | N22: MG | O22: G | P22: G | Q22: VG | R22: VG | S22: MP | T22: G | U22: MG | V22: G | W22: G | X22: F | Y22: G | Z22: MG | AA22: G | AB22: MP | AC22: F | AD22: VG | AF22: C18 | AG22: =SQRT(1-((((1-C44^2))^$C$25)*(((1-G44^2))^$G$25)*(((1-K44^2))^$K$25)*(((1-O44^2))^$O$25)*(((1-S44^2))^$S$25)*(((1-W44^2))^$W$25)*(((1-AA44^2))^$AA$25))) -> 0.59426892 | AH22: =SQRT(1-((((1-D44^2))^$C$25)*(((1-H44^2))^$G$25)*(((1-L44^2))^$K$25)*(((1-P44^2))^$O$25)*(((1-T44^2))^$S$25)*(((1-X44^2))^$W$25)*(((1-AB44^2))^$AA$25))) -> 0.56801636 | AI22: =SQRT(1-((((1-E44^2))^$C$25)*(((1-I44^2))^$G$25)*(((1-M44^2))^$K$25)*(((1-Q44^2))^$O$25)*(((1-U44^2))^$S$25)*(((1-Y44^2))^$W$25)*(((1-AC44^2))^$AA$25))) -> 0.68242246 | AJ22: =SQRT(1-((((1-F44^2))^$C$25)*(((1-J44^2))^$G$25)*(((1-N44^2))^$K$25)*(((1-R44^2))^$O$25)*(((1-V44^2))^$S$25)*(((1-Z44^2))^$W$25)*(((1-AD44^2))^$AA$25))) -> 0.70080222 | AL22: C18 | AM22: =(1+AG22^2-AG44^2)/2 -> 0.5564733 | AN22: =(1+AH22^2-AH44^2)/2 -> 0.52278185 | AO22: =(1+AI22^2-AI44^2)/2 -> 0.65539527 | AP22: =(1+AJ22^2-AJ44^2)/2 -> 0.66941994 | AQ22: 1 | AR22: =SUM(AM22:AP22) -> 2.4040704 | AT22: C18 | AU22: =AM22/SUM($AM22:$AP22) -> 0.2314713 | AV22: =AN22/SUM($AM22:$AP22) -> 0.21745697 | AW22: =AO22/SUM($AM22:$AP22) -> 0.27261901 | AX22: =AP22/SUM($AM22:$AP22) -> 0.27845272 | AY22: =AQ22/SUM($AM22:$AP22) -> 0.4159612 | BA22: sort 4-3 | BB22: =BB15-BB14 -> 0.056389639 | BC22: =BC15-BC14 -> 0.0006872952 | BD22: =BD15-BD14 -> 0.017820191 | BE22: =BE15-BE14 -> 0.014189287 | BF22: =BF15-BF14 -> 0.052679056 | BG22: =BG15-BG14 -> 0.01969907 | BH22: =BH15-BH14 -> 0.039595218 | BI22: =BI15-BI14 -> 0.059933695 | ... BS22: =BS15-BS14 -> 0.0058337188
BA23: sort as-4 | BB23: =BB16-BB15 -> 0.17421467 | BC23: =BC16-BC15 -> 0.2748072 | BD23: =BD16-BD15 -> 0.21462316 | BE23: =BE16-BE15 -> 0.13947775 | BF23: =BF16-BF15 -> 0.16059466 | BG23: =BG16-BG15 -> 0.12632791 | BH23: =BH16-BH15 -> 0.094837599 | BI23: =BI16-BI15 -> 0.10005807 | ... BS23: =BS16-BS15 -> 0.13750848
B24: µ values | AF24: v values
B25: Expert Weights | C25: =1/7 -> 0.14285714 | G25: =1/7 -> 0.14285714 | K25: =1/7 -> 0.14285714 | O25: =1/7 -> 0.14285714 | S25: =1/7 -> 0.14285714 | W25: =1/7 -> 0.14285714 | AA25: =1/7 -> 0.14285714 | BA25: Step 7. Indifference threshold
C26: A1 | D26: A2 | E26: A3 | F26: A4 | G26: A1 | H26: A2 | I26: A3 | J26: A4 | K26: A1 | L26: A2 | M26: A3 | N26: A4 | O26: A1 | P26: A2 | Q26: A3 | R26: A4 | S26: A1 | T26: A2 | U26: A3 | V26: A4 | W26: A1 | X26: A2 | Y26: A3 | Z26: A4 | AA26: A1 | AB26: A2 | AC26: A3 | AD26: A4 | AG26: A1 | AH26: A2 | AI26: A3 | AJ26: A4 | BA26: Itj | BB26: 0.1 | BC26: 0.1 | BD26: 0.1 | BE26: 0.05 | BF26: 0.05 | BG26: 0.05 | BH26: 0.1 | BI26: 0.1 | BJ26: 0.03 | BK26: 0.03 | BL26: 0.1 | BM26: 0.1 | BN26: 0.15 | BO26: 0.1 | BP26: 0.15 | BQ26: 0.15 | BR26: 0.05 | BS26: 0.15
B27: C1 | C27: =IF(C5="VG",0.8,IF(C5="G",0.7,IF(C5="MG",0.6,IF(C5="F",0.45,IF(C5="MP",0.35,IF(C5="P",0.3,IF(C5="VP",0.2,"ERROR"))))))) -> 0.35 | D27: =IF(D5="VG",0.8,IF(D5="G",0.7,IF(D5="MG",0.6,IF(D5="F",0.45,IF(D5="MP",0.35,IF(D5="P",0.3,IF(D5="VP",0.2,"ERROR"))))))) -> 0.6 | E27: =IF(E5="VG",0.8,IF(E5="G",0.7,IF(E5="MG",0.6,IF(E5="F",0.45,IF(E5="MP",0.35,IF(E5="P",0.3,IF(E5="VP",0.2,"ERROR"))))))) -> 0.3 | F27: =IF(F5="VG",0.8,IF(F5="G",0.7,IF(F5="MG",0.6,IF(F5="F",0.45,IF(F5="MP",0.35,IF(F5="P",0.3,IF(F5="VP",0.2,"ERROR"))))))) -> 0.35 | G27: =IF(G5="VG",0.8,IF(G5="G",0.7,IF(G5="MG",0.6,IF(G5="F",0.45,IF(G5="MP",0.35,IF(G5="P",0.3,IF(G5="VP",0.2,"ERROR"))))))) -> 0.35 | H27: =IF(H5="VG",0.8,IF(H5="G",0.7,IF(H5="MG",0.6,IF(H5="F",0.45,IF(H5="MP",0.35,IF(H5="P",0.3,IF(H5="VP",0.2,"ERROR"))))))) -> 0.45 | I27: =IF(I5="VG",0.8,IF(I5="G",0.7,IF(I5="MG",0.6,IF(I5="F",0.45,IF(I5="MP",0.35,IF(I5="P",0.3,IF(I5="VP",0.2,"ERROR"))))))) -> 0.7 | J27: =IF(J5="VG",0.8,IF(J5="G",0.7,IF(J5="MG",0.6,IF(J5="F",0.45,IF(J5="MP",0.35,IF(J5="P",0.3,IF(J5="VP",0.2,"ERROR"))))))) -> 0.3 | ... AD27: =IF(AD5="VG",0.8,IF(AD5="G",0.7,IF(AD5="MG",0.6,IF(AD5="F",0.45,IF(AD5="MP",0.35,IF(AD5="P",0.3,IF(AD5="VP",0.2,"ERROR"))))))) -> 0.45 | AF27: C1 | AG27: =(C48^$C$25)*(G48^$G$25)*(K48^$K$25)*(O48^$O$25)*(S48^$S$25)*(W48^$W$25)*(AA48^$AA$25) -> 0.64457449 | AH27: =(D48^$C$25)*(H48^$G$25)*(L48^$K$25)*(P48^$O$25)*(T48^$S$25)*(X48^$W$25)*(AB48^$AA$25) -> 0.52272668 | AI27: =(E48^$C$25)*(I48^$G$25)*(M48^$K$25)*(Q48^$O$25)*(U48^$S$25)*(Y48^$W$25)*(AC48^$AA$25) -> 0.40896222 | AJ27: =(F48^$C$25)*(J48^$G$25)*(N48^$K$25)*(R48^$O$25)*(V48^$S$25)*(Z48^$W$25)*(AD48^$AA$25) -> 0.59921191 | BB27: {=TRANSPOSE(AR5:AR22)} -> 2.0426458 | BC27: 1.7140851 | BD27: 2.0471701 | BE27: 2.4706789 | BF27: 2.1900231 | BG27: 2.4941614 | BH27: 2.6147672 | BI27: 2.4783432 | BJ27: 2.5766128 | BK27: 2.5347061 | BL27: 2.3272127 | BM27: 2.5250664 | BN27: 2.3570502 | BO27: 2.6554534 | BP27: 2.2038293 | BQ27: 2.2854891 | BR27: 2.566624 | BS27: 2.4040704
B28: C2 | C28: =IF(C6="VG",0.8,IF(C6="G",0.7,IF(C6="MG",0.6,IF(C6="F",0.45,IF(C6="MP",0.35,IF(C6="P",0.3,IF(C6="VP",0.2,"ERROR"))))))) -> 0.35 | D28: =IF(D6="VG",0.8,IF(D6="G",0.7,IF(D6="MG",0.6,IF(D6="F",0.45,IF(D6="MP",0.35,IF(D6="P",0.3,IF(D6="VP",0.2,"ERROR"))))))) -> 0.6 | E28: =IF(E6="VG",0.8,IF(E6="G",0.7,IF(E6="MG",0.6,IF(E6="F",0.45,IF(E6="MP",0.35,IF(E6="P",0.3,IF(E6="VP",0.2,"ERROR"))))))) -> 0.3 | F28: =IF(F6="VG",0.8,IF(F6="G",0.7,IF(F6="MG",0.6,IF(F6="F",0.45,IF(F6="MP",0.35,IF(F6="P",0.3,IF(F6="VP",0.2,"ERROR"))))))) -> 0.35 | G28: =IF(G6="VG",0.8,IF(G6="G",0.7,IF(G6="MG",0.6,IF(G6="F",0.45,IF(G6="MP",0.35,IF(G6="P",0.3,IF(G6="VP",0.2,"ERROR"))))))) -> 0.35 | H28: =IF(H6="VG",0.8,IF(H6="G",0.7,IF(H6="MG",0.6,IF(H6="F",0.45,IF(H6="MP",0.35,IF(H6="P",0.3,IF(H6="VP",0.2,"ERROR"))))))) -> 0.6 | I28: =IF(I6="VG",0.8,IF(I6="G",0.7,IF(I6="MG",0.6,IF(I6="F",0.45,IF(I6="MP",0.35,IF(I6="P",0.3,IF(I6="VP",0.2,"ERROR"))))))) -> 0.3 | J28: =IF(J6="VG",0.8,IF(J6="G",0.7,IF(J6="MG",0.6,IF(J6="F",0.45,IF(J6="MP",0.35,IF(J6="P",0.3,IF(J6="VP",0.2,"ERROR"))))))) -> 0.35 | ... AD28: =IF(AD6="VG",0.8,IF(AD6="G",0.7,IF(AD6="MG",0.6,IF(AD6="F",0.45,IF(AD6="MP",0.35,IF(AD6="P",0.3,IF(AD6="VP",0.2,"ERROR"))))))) -> 0.45 | AF28: C2 | AG28: =(C49^$C$25)*(G49^$G$25)*(K49^$K$25)*(O49^$O$25)*(S49^$S$25)*(W49^$W$25)*(AA49^$AA$25) -> 0.68861302 | AH28: =(D49^$C$25)*(H49^$G$25)*(L49^$K$25)*(P49^$O$25)*(T49^$S$25)*(X49^$W$25)*(AB49^$AA$25) -> 0.52272668 | AI28: =(E49^$C$25)*(I49^$G$25)*(M49^$K$25)*(Q49^$O$25)*(U49^$S$25)*(Y49^$W$25)*(AC49^$AA$25) -> 0.5409036 | AJ28: =(F49^$C$25)*(J49^$G$25)*(N49^$K$25)*(R49^$O$25)*(V49^$S$25)*(Z49^$W$25)*(AD49^$AA$25) -> 0.73294283 | BA28: Ntj | BB28: =BB26/BB27 -> 0.048956113 | BC28: =BC26/BC27 -> 0.05834016 | BD28: =BD26/BD27 -> 0.048847919 | BE28: =BE26/BE27 -> 0.020237352 | BF28: =BF26/BF27 -> 0.02283081 | BG28: =BG26/BG27 -> 0.020046818 | BH28: =BH26/BH27 -> 0.038244323 | BI28: =BI26/BI27 -> 0.040349537 | ... BS28: =BS26/BS27 -> 0.06239418
B29: C3 | C29: =IF(C7="VG",0.8,IF(C7="G",0.7,IF(C7="MG",0.6,IF(C7="F",0.45,IF(C7="MP",0.35,IF(C7="P",0.3,IF(C7="VP",0.2,"ERROR"))))))) -> 0.35 | D29: =IF(D7="VG",0.8,IF(D7="G",0.7,IF(D7="MG",0.6,IF(D7="F",0.45,IF(D7="MP",0.35,IF(D7="P",0.3,IF(D7="VP",0.2,"ERROR"))))))) -> 0.6 | E29: =IF(E7="VG",0.8,IF(E7="G",0.7,IF(E7="MG",0.6,IF(E7="F",0.45,IF(E7="MP",0.35,IF(E7="P",0.3,IF(E7="VP",0.2,"ERROR"))))))) -> 0.45 | F29: =IF(F7="VG",0.8,IF(F7="G",0.7,IF(F7="MG",0.6,IF(F7="F",0.45,IF(F7="MP",0.35,IF(F7="P",0.3,IF(F7="VP",0.2,"ERROR"))))))) -> 0.35 | G29: =IF(G7="VG",0.8,IF(G7="G",0.7,IF(G7="MG",0.6,IF(G7="F",0.45,IF(G7="MP",0.35,IF(G7="P",0.3,IF(G7="VP",0.2,"ERROR"))))))) -> 0.3 | H29: =IF(H7="VG",0.8,IF(H7="G",0.7,IF(H7="MG",0.6,IF(H7="F",0.45,IF(H7="MP",0.35,IF(H7="P",0.3,IF(H7="VP",0.2,"ERROR"))))))) -> 0.45 | I29: =IF(I7="VG",0.8,IF(I7="G",0.7,IF(I7="MG",0.6,IF(I7="F",0.45,IF(I7="MP",0.35,IF(I7="P",0.3,IF(I7="VP",0.2,"ERROR"))))))) -> 0.7 | J29: =IF(J7="VG",0.8,IF(J7="G",0.7,IF(J7="MG",0.6,IF(J7="F",0.45,IF(J7="MP",0.35,IF(J7="P",0.3,IF(J7="VP",0.2,"ERROR"))))))) -> 0.6 | ... AD29: =IF(AD7="VG",0.8,IF(AD7="G",0.7,IF(AD7="MG",0.6,IF(AD7="F",0.45,IF(AD7="MP",0.35,IF(AD7="P",0.3,IF(AD7="VP",0.2,"ERROR"))))))) -> 0.6 | AF29: C3 | AG29: =(C50^$C$25)*(G50^$G$25)*(K50^$K$25)*(O50^$O$25)*(S50^$S$25)*(W50^$W$25)*(AA50^$AA$25) -> 0.52915377 | AH29: =(D50^$C$25)*(H50^$G$25)*(L50^$K$25)*(P50^$O$25)*(T50^$S$25)*(X50^$W$25)*(AB50^$AA$25) -> 0.50099405 | AI29: =(E50^$C$25)*(I50^$G$25)*(M50^$K$25)*(Q50^$O$25)*(U50^$S$25)*(Y50^$W$25)*(AC50^$AA$25) -> 0.60778669 | AJ29: =(F50^$C$25)*(J50^$G$25)*(N50^$K$25)*(R50^$O$25)*(V50^$S$25)*(Z50^$W$25)*(AD50^$AA$25) -> 0.54468688
B30: C4 | C30: =IF(C8="VG",0.8,IF(C8="G",0.7,IF(C8="MG",0.6,IF(C8="F",0.45,IF(C8="MP",0.35,IF(C8="P",0.3,IF(C8="VP",0.2,"ERROR"))))))) -> 0.7 | D30: =IF(D8="VG",0.8,IF(D8="G",0.7,IF(D8="MG",0.6,IF(D8="F",0.45,IF(D8="MP",0.35,IF(D8="P",0.3,IF(D8="VP",0.2,"ERROR"))))))) -> 0.6 | E30: =IF(E8="VG",0.8,IF(E8="G",0.7,IF(E8="MG",0.6,IF(E8="F",0.45,IF(E8="MP",0.35,IF(E8="P",0.3,IF(E8="VP",0.2,"ERROR"))))))) -> 0.7 | F30: =IF(F8="VG",0.8,IF(F8="G",0.7,IF(F8="MG",0.6,IF(F8="F",0.45,IF(F8="MP",0.35,IF(F8="P",0.3,IF(F8="VP",0.2,"ERROR"))))))) -> 0.7 | G30: =IF(G8="VG",0.8,IF(G8="G",0.7,IF(G8="MG",0.6,IF(G8="F",0.45,IF(G8="MP",0.35,IF(G8="P",0.3,IF(G8="VP",0.2,"ERROR"))))))) -> 0.6 | H30: =IF(H8="VG",0.8,IF(H8="G",0.7,IF(H8="MG",0.6,IF(H8="F",0.45,IF(H8="MP",0.35,IF(H8="P",0.3,IF(H8="VP",0.2,"ERROR"))))))) -> 0.45 | I30: =IF(I8="VG",0.8,IF(I8="G",0.7,IF(I8="MG",0.6,IF(I8="F",0.45,IF(I8="MP",0.35,IF(I8="P",0.3,IF(I8="VP",0.2,"ERROR"))))))) -> 0.7 | J30: =IF(J8="VG",0.8,IF(J8="G",0.7,IF(J8="MG",0.6,IF(J8="F",0.45,IF(J8="MP",0.35,IF(J8="P",0.3,IF(J8="VP",0.2,"ERROR"))))))) -> 0.35 | ... AD30: =IF(AD8="VG",0.8,IF(AD8="G",0.7,IF(AD8="MG",0.6,IF(AD8="F",0.45,IF(AD8="MP",0.35,IF(AD8="P",0.3,IF(AD8="VP",0.2,"ERROR"))))))) -> 0.8 | AF30: C4 | AG30: =(C51^$C$25)*(G51^$G$25)*(K51^$K$25)*(O51^$O$25)*(S51^$S$25)*(W51^$W$25)*(AA51^$AA$25) -> 0.42912464 | AH30: =(D51^$C$25)*(H51^$G$25)*(L51^$K$25)*(P51^$O$25)*(T51^$S$25)*(X51^$W$25)*(AB51^$AA$25) -> 0.39358591 | AI30: =(E51^$C$25)*(I51^$G$25)*(M51^$K$25)*(Q51^$O$25)*(U51^$S$25)*(Y51^$W$25)*(AC51^$AA$25) -> 0.42338183 | AJ30: =(F51^$C$25)*(J51^$G$25)*(N51^$K$25)*(R51^$O$25)*(V51^$S$25)*(Z51^$W$25)*(AD51^$AA$25) -> 0.47943613 | BA30: Step 8. Significant ordered distances
B31: C5 | C31: =IF(C9="VG",0.8,IF(C9="G",0.7,IF(C9="MG",0.6,IF(C9="F",0.45,IF(C9="MP",0.35,IF(C9="P",0.3,IF(C9="VP",0.2,"ERROR"))))))) -> 0.35 | D31: =IF(D9="VG",0.8,IF(D9="G",0.7,IF(D9="MG",0.6,IF(D9="F",0.45,IF(D9="MP",0.35,IF(D9="P",0.3,IF(D9="VP",0.2,"ERROR"))))))) -> 0.6 | E31: =IF(E9="VG",0.8,IF(E9="G",0.7,IF(E9="MG",0.6,IF(E9="F",0.45,IF(E9="MP",0.35,IF(E9="P",0.3,IF(E9="VP",0.2,"ERROR"))))))) -> 0.7 | F31: =IF(F9="VG",0.8,IF(F9="G",0.7,IF(F9="MG",0.6,IF(F9="F",0.45,IF(F9="MP",0.35,IF(F9="P",0.3,IF(F9="VP",0.2,"ERROR"))))))) -> 0.35 | G31: =IF(G9="VG",0.8,IF(G9="G",0.7,IF(G9="MG",0.6,IF(G9="F",0.45,IF(G9="MP",0.35,IF(G9="P",0.3,IF(G9="VP",0.2,"ERROR"))))))) -> 0.7 | H31: =IF(H9="VG",0.8,IF(H9="G",0.7,IF(H9="MG",0.6,IF(H9="F",0.45,IF(H9="MP",0.35,IF(H9="P",0.3,IF(H9="VP",0.2,"ERROR"))))))) -> 0.6 | I31: =IF(I9="VG",0.8,IF(I9="G",0.7,IF(I9="MG",0.6,IF(I9="F",0.45,IF(I9="MP",0.35,IF(I9="P",0.3,IF(I9="VP",0.2,"ERROR"))))))) -> 0.35 | J31: =IF(J9="VG",0.8,IF(J9="G",0.7,IF(J9="MG",0.6,IF(J9="F",0.45,IF(J9="MP",0.35,IF(J9="P",0.3,IF(J9="VP",0.2,"ERROR"))))))) -> 0.7 | ... AD31: =IF(AD9="VG",0.8,IF(AD9="G",0.7,IF(AD9="MG",0.6,IF(AD9="F",0.45,IF(AD9="MP",0.35,IF(AD9="P",0.3,IF(AD9="VP",0.2,"ERROR"))))))) -> 0.45 | AF31: C5 | AG31: =(C52^$C$25)*(G52^$G$25)*(K52^$K$25)*(O52^$O$25)*(S52^$S$25)*(W52^$W$25)*(AA52^$AA$25) -> 0.55777315 | AH31: =(D52^$C$25)*(H52^$G$25)*(L52^$K$25)*(P52^$O$25)*(T52^$S$25)*(X52^$W$25)*(AB52^$AA$25) -> 0.53352275 | AI31: =(E52^$C$25)*(I52^$G$25)*(M52^$K$25)*(Q52^$O$25)*(U52^$S$25)*(Y52^$W$25)*(AC52^$AA$25) -> 0.39025888 | AJ31: =(F52^$C$25)*(J52^$G$25)*(N52^$K$25)*(R52^$O$25)*(V52^$S$25)*(Z52^$W$25)*(AD52^$AA$25) -> 0.51573124 | BB31: C1 | BC31: C2 | BD31: C3 | BE31: C4 | BF31: C5 | BG31: C6 | BH31: C7 | BI31: C8 | BJ31: C9 | BK31: C10 | BL31: C11 | BM31: C12 | BN31: C13 | BO31: C14 | BP31: C15 | BQ31: C16 | BR31: C17 | BS31: C18
B32: C6 | C32: =IF(C10="VG",0.8,IF(C10="G",0.7,IF(C10="MG",0.6,IF(C10="F",0.45,IF(C10="MP",0.35,IF(C10="P",0.3,IF(C10="VP",0.2,"ERROR"))))))) -> 0.7 | D32: =IF(D10="VG",0.8,IF(D10="G",0.7,IF(D10="MG",0.6,IF(D10="F",0.45,IF(D10="MP",0.35,IF(D10="P",0.3,IF(D10="VP",0.2,"ERROR"))))))) -> 0.6 | E32: =IF(E10="VG",0.8,IF(E10="G",0.7,IF(E10="MG",0.6,IF(E10="F",0.45,IF(E10="MP",0.35,IF(E10="P",0.3,IF(E10="VP",0.2,"ERROR"))))))) -> 0.7 | F32: =IF(F10="VG",0.8,IF(F10="G",0.7,IF(F10="MG",0.6,IF(F10="F",0.45,IF(F10="MP",0.35,IF(F10="P",0.3,IF(F10="VP",0.2,"ERROR"))))))) -> 0.8 | G32: =IF(G10="VG",0.8,IF(G10="G",0.7,IF(G10="MG",0.6,IF(G10="F",0.45,IF(G10="MP",0.35,IF(G10="P",0.3,IF(G10="VP",0.2,"ERROR"))))))) -> 0.6 | H32: =IF(H10="VG",0.8,IF(H10="G",0.7,IF(H10="MG",0.6,IF(H10="F",0.45,IF(H10="MP",0.35,IF(H10="P",0.3,IF(H10="VP",0.2,"ERROR"))))))) -> 0.7 | I32: =IF(I10="VG",0.8,IF(I10="G",0.7,IF(I10="MG",0.6,IF(I10="F",0.45,IF(I10="MP",0.35,IF(I10="P",0.3,IF(I10="VP",0.2,"ERROR"))))))) -> 0.6 | J32: =IF(J10="VG",0.8,IF(J10="G",0.7,IF(J10="MG",0.6,IF(J10="F",0.45,IF(J10="MP",0.35,IF(J10="P",0.3,IF(J10="VP",0.2,"ERROR"))))))) -> 0.45 | ... AD32: =IF(AD10="VG",0.8,IF(AD10="G",0.7,IF(AD10="MG",0.6,IF(AD10="F",0.45,IF(AD10="MP",0.35,IF(AD10="P",0.3,IF(AD10="VP",0.2,"ERROR"))))))) -> 0.7 | AF32: C6 | AG32: =(C53^$C$25)*(G53^$G$25)*(K53^$K$25)*(O53^$O$25)*(S53^$S$25)*(W53^$W$25)*(AA53^$AA$25) -> 0.40780693 | AH32: =(D53^$C$25)*(H53^$G$25)*(L53^$K$25)*(P53^$O$25)*(T53^$S$25)*(X53^$W$25)*(AB53^$AA$25) -> 0.37084984 | AI32: =(E53^$C$25)*(I53^$G$25)*(M53^$K$25)*(Q53^$O$25)*(U53^$S$25)*(Y53^$W$25)*(AC53^$AA$25) -> 0.47208148 | AJ32: =(F53^$C$25)*(J53^$G$25)*(N53^$K$25)*(R53^$O$25)*(V53^$S$25)*(Z53^$W$25)*(AD53^$AA$25) -> 0.45561909 | BA32: sort 2-1 | BB32: =IF(BB20<BB$28,0,BB20-BB$28) -> 0 | BC32: =IF(BC20<BC$28,0,BC20-BC$28) -> 0 | BD32: =IF(BD20<BD$28,0,BD20-BD$28) -> 0 | BE32: =IF(BE20<BE$28,0,BE20-BE$28) -> 0 | BF32: =IF(BF20<BF$28,0,BF20-BF$28) -> 0 | BG32: =IF(BG20<BG$28,0,BG20-BG$28) -> 0 | BH32: =IF(BH20<BH$28,0,BH20-BH$28) -> 0 | BI32: =IF(BI20<BI$28,0,BI20-BI$28) -> 0 | ... BS32: =IF(BS20<BS$28,0,BS20-BS$28) -> 0
B33: C7 | C33: =IF(C11="VG",0.8,IF(C11="G",0.7,IF(C11="MG",0.6,IF(C11="F",0.45,IF(C11="MP",0.35,IF(C11="P",0.3,IF(C11="VP",0.2,"ERROR"))))))) -> 0.6 | D33: =IF(D11="VG",0.8,IF(D11="G",0.7,IF(D11="MG",0.6,IF(D11="F",0.45,IF(D11="MP",0.35,IF(D11="P",0.3,IF(D11="VP",0.2,"ERROR"))))))) -> 0.7 | E33: =IF(E11="VG",0.8,IF(E11="G",0.7,IF(E11="MG",0.6,IF(E11="F",0.45,IF(E11="MP",0.35,IF(E11="P",0.3,IF(E11="VP",0.2,"ERROR"))))))) -> 0.7 | F33: =IF(F11="VG",0.8,IF(F11="G",0.7,IF(F11="MG",0.6,IF(F11="F",0.45,IF(F11="MP",0.35,IF(F11="P",0.3,IF(F11="VP",0.2,"ERROR"))))))) -> 0.8 | G33: =IF(G11="VG",0.8,IF(G11="G",0.7,IF(G11="MG",0.6,IF(G11="F",0.45,IF(G11="MP",0.35,IF(G11="P",0.3,IF(G11="VP",0.2,"ERROR"))))))) -> 0.35 | H33: =IF(H11="VG",0.8,IF(H11="G",0.7,IF(H11="MG",0.6,IF(H11="F",0.45,IF(H11="MP",0.35,IF(H11="P",0.3,IF(H11="VP",0.2,"ERROR"))))))) -> 0.35 | I33: =IF(I11="VG",0.8,IF(I11="G",0.7,IF(I11="MG",0.6,IF(I11="F",0.45,IF(I11="MP",0.35,IF(I11="P",0.3,IF(I11="VP",0.2,"ERROR"))))))) -> 0.45 | J33: =IF(J11="VG",0.8,IF(J11="G",0.7,IF(J11="MG",0.6,IF(J11="F",0.45,IF(J11="MP",0.35,IF(J11="P",0.3,IF(J11="VP",0.2,"ERROR"))))))) -> 0.7 | ... AD33: =IF(AD11="VG",0.8,IF(AD11="G",0.7,IF(AD11="MG",0.6,IF(AD11="F",0.45,IF(AD11="MP",0.35,IF(AD11="P",0.3,IF(AD11="VP",0.2,"ERROR"))))))) -> 0.8 | AF33: C7 | AG33: =(C54^$C$25)*(G54^$G$25)*(K54^$K$25)*(O54^$O$25)*(S54^$S$25)*(W54^$W$25)*(AA54^$AA$25) -> 0.43512265 | AH33: =(D54^$C$25)*(H54^$G$25)*(L54^$K$25)*(P54^$O$25)*(T54^$S$25)*(X54^$W$25)*(AB54^$AA$25) -> 0.40171478 | AI33: =(E54^$C$25)*(I54^$G$25)*(M54^$K$25)*(Q54^$O$25)*(U54^$S$25)*(Y54^$W$25)*(AC54^$AA$25) -> 0.46252871 | AJ33: =(F54^$C$25)*(J54^$G$25)*(N54^$K$25)*(R54^$O$25)*(V54^$S$25)*(Z54^$W$25)*(AD54^$AA$25) -> 0.3135082 | BA33: sort 3-2 | BB33: =IF(BB21<BB$28,0,BB21-BB$28) -> 0 | BC33: =IF(BC21<BC$28,0,BC21-BC$28) -> 0.042398626 | BD33: =IF(BD21<BD$28,0,BD21-BD$28) -> 0 | BE33: =IF(BE21<BE$28,0,BE21-BE$28) -> 0 | BF33: =IF(BF21<BF$28,0,BF21-BF$28) -> 0 | BG33: =IF(BG21<BG$28,0,BG21-BG$28) -> 0 | BH33: =IF(BH21<BH$28,0,BH21-BH$28) -> 0 | BI33: =IF(BI21<BI$28,0,BI21-BI$28) -> 0 | ... BS33: =IF(BS21<BS$28,0,BS21-BS$28) -> 0
B34: C8 | C34: =IF(C12="VG",0.8,IF(C12="G",0.7,IF(C12="MG",0.6,IF(C12="F",0.45,IF(C12="MP",0.35,IF(C12="P",0.3,IF(C12="VP",0.2,"ERROR"))))))) -> 0.6 | D34: =IF(D12="VG",0.8,IF(D12="G",0.7,IF(D12="MG",0.6,IF(D12="F",0.45,IF(D12="MP",0.35,IF(D12="P",0.3,IF(D12="VP",0.2,"ERROR"))))))) -> 0.7 | E34: =IF(E12="VG",0.8,IF(E12="G",0.7,IF(E12="MG",0.6,IF(E12="F",0.45,IF(E12="MP",0.35,IF(E12="P",0.3,IF(E12="VP",0.2,"ERROR"))))))) -> 0.7 | F34: =IF(F12="VG",0.8,IF(F12="G",0.7,IF(F12="MG",0.6,IF(F12="F",0.45,IF(F12="MP",0.35,IF(F12="P",0.3,IF(F12="VP",0.2,"ERROR"))))))) -> 0.8 | G34: =IF(G12="VG",0.8,IF(G12="G",0.7,IF(G12="MG",0.6,IF(G12="F",0.45,IF(G12="MP",0.35,IF(G12="P",0.3,IF(G12="VP",0.2,"ERROR"))))))) -> 0.45 | H34: =IF(H12="VG",0.8,IF(H12="G",0.7,IF(H12="MG",0.6,IF(H12="F",0.45,IF(H12="MP",0.35,IF(H12="P",0.3,IF(H12="VP",0.2,"ERROR"))))))) -> 0.45 | I34: =IF(I12="VG",0.8,IF(I12="G",0.7,IF(I12="MG",0.6,IF(I12="F",0.45,IF(I12="MP",0.35,IF(I12="P",0.3,IF(I12="VP",0.2,"ERROR"))))))) -> 0.45 | J34: =IF(J12="VG",0.8,IF(J12="G",0.7,IF(J12="MG",0.6,IF(J12="F",0.45,IF(J12="MP",0.35,IF(J12="P",0.3,IF(J12="VP",0.2,"ERROR"))))))) -> 0.7 | ... AD34: =IF(AD12="VG",0.8,IF(AD12="G",0.7,IF(AD12="MG",0.6,IF(AD12="F",0.45,IF(AD12="MP",0.35,IF(AD12="P",0.3,IF(AD12="VP",0.2,"ERROR"))))))) -> 0.8 | AF34: C8 | AG34: =(C55^$C$25)*(G55^$G$25)*(K55^$K$25)*(O55^$O$25)*(S55^$S$25)*(W55^$W$25)*(AA55^$AA$25) -> 0.51214908 | AH34: =(D55^$C$25)*(H55^$G$25)*(L55^$K$25)*(P55^$O$25)*(T55^$S$25)*(X55^$W$25)*(AB55^$AA$25) -> 0.46252871 | AI34: =(E55^$C$25)*(I55^$G$25)*(M55^$K$25)*(Q55^$O$25)*(U55^$S$25)*(Y55^$W$25)*(AC55^$AA$25) -> 0.45245445 | AJ34: =(F55^$C$25)*(J55^$G$25)*(N55^$K$25)*(R55^$O$25)*(V55^$S$25)*(Z55^$W$25)*(AD55^$AA$25) -> 0.3135082 | BA34: sort 4-3 | BB34: =IF(BB22<BB$28,0,BB22-BB$28) -> 0.0074335258 | BC34: =IF(BC22<BC$28,0,BC22-BC$28) -> 0 | BD34: =IF(BD22<BD$28,0,BD22-BD$28) -> 0 | BE34: =IF(BE22<BE$28,0,BE22-BE$28) -> 0 | BF34: =IF(BF22<BF$28,0,BF22-BF$28) -> 0.029848246 | BG34: =IF(BG22<BG$28,0,BG22-BG$28) -> 0 | BH34: =IF(BH22<BH$28,0,BH22-BH$28) -> 0.0013508954 | BI34: =IF(BI22<BI$28,0,BI22-BI$28) -> 0.019584158 | ... BS34: =IF(BS22<BS$28,0,BS22-BS$28) -> 0
B35: C9 | C35: =IF(C13="VG",0.8,IF(C13="G",0.7,IF(C13="MG",0.6,IF(C13="F",0.45,IF(C13="MP",0.35,IF(C13="P",0.3,IF(C13="VP",0.2,"ERROR"))))))) -> 0.7 | D35: =IF(D13="VG",0.8,IF(D13="G",0.7,IF(D13="MG",0.6,IF(D13="F",0.45,IF(D13="MP",0.35,IF(D13="P",0.3,IF(D13="VP",0.2,"ERROR"))))))) -> 0.7 | E35: =IF(E13="VG",0.8,IF(E13="G",0.7,IF(E13="MG",0.6,IF(E13="F",0.45,IF(E13="MP",0.35,IF(E13="P",0.3,IF(E13="VP",0.2,"ERROR"))))))) -> 0.6 | F35: =IF(F13="VG",0.8,IF(F13="G",0.7,IF(F13="MG",0.6,IF(F13="F",0.45,IF(F13="MP",0.35,IF(F13="P",0.3,IF(F13="VP",0.2,"ERROR"))))))) -> 0.8 | G35: =IF(G13="VG",0.8,IF(G13="G",0.7,IF(G13="MG",0.6,IF(G13="F",0.45,IF(G13="MP",0.35,IF(G13="P",0.3,IF(G13="VP",0.2,"ERROR"))))))) -> 0.6 | H35: =IF(H13="VG",0.8,IF(H13="G",0.7,IF(H13="MG",0.6,IF(H13="F",0.45,IF(H13="MP",0.35,IF(H13="P",0.3,IF(H13="VP",0.2,"ERROR"))))))) -> 0.7 | I35: =IF(I13="VG",0.8,IF(I13="G",0.7,IF(I13="MG",0.6,IF(I13="F",0.45,IF(I13="MP",0.35,IF(I13="P",0.3,IF(I13="VP",0.2,"ERROR"))))))) -> 0.7 | J35: =IF(J13="VG",0.8,IF(J13="G",0.7,IF(J13="MG",0.6,IF(J13="F",0.45,IF(J13="MP",0.35,IF(J13="P",0.3,IF(J13="VP",0.2,"ERROR"))))))) -> 0.35 | ... AD35: =IF(AD13="VG",0.8,IF(AD13="G",0.7,IF(AD13="MG",0.6,IF(AD13="F",0.45,IF(AD13="MP",0.35,IF(AD13="P",0.3,IF(AD13="VP",0.2,"ERROR"))))))) -> 0.8 | AF35: C9 | AG35: =(C56^$C$25)*(G56^$G$25)*(K56^$K$25)*(O56^$O$25)*(S56^$S$25)*(W56^$W$25)*(AA56^$AA$25) -> 0.40780693 | AH35: =(D56^$C$25)*(H56^$G$25)*(L56^$K$25)*(P56^$O$25)*(T56^$S$25)*(X56^$W$25)*(AB56^$AA$25) -> 0.37084984 | AI35: =(E56^$C$25)*(I56^$G$25)*(M56^$K$25)*(Q56^$O$25)*(U56^$S$25)*(Y56^$W$25)*(AC56^$AA$25) -> 0.47208148 | AJ35: =(F56^$C$25)*(J56^$G$25)*(N56^$K$25)*(R56^$O$25)*(V56^$S$25)*(Z56^$W$25)*(AD56^$AA$25) -> 0.3956901 | BA35: sort as-4 | BB35: =IF(BB23<BB$28,0,BB23-BB$28) -> 0.12525856 | BC35: =IF(BC23<BC$28,0,BC23-BC$28) -> 0.21646704 | BD35: =IF(BD23<BD$28,0,BD23-BD$28) -> 0.16577524 | BE35: =IF(BE23<BE$28,0,BE23-BE$28) -> 0.11924039 | BF35: =IF(BF23<BF$28,0,BF23-BF$28) -> 0.13776385 | BG35: =IF(BG23<BG$28,0,BG23-BG$28) -> 0.10628109 | BH35: =IF(BH23<BH$28,0,BH23-BH$28) -> 0.056593277 | BI35: =IF(BI23<BI$28,0,BI23-BI$28) -> 0.059708536 | ... BS35: =IF(BS23<BS$28,0,BS23-BS$28) -> 0.075114298
B36: C10 | C36: =IF(C14="VG",0.8,IF(C14="G",0.7,IF(C14="MG",0.6,IF(C14="F",0.45,IF(C14="MP",0.35,IF(C14="P",0.3,IF(C14="VP",0.2,"ERROR"))))))) -> 0.6 | D36: =IF(D14="VG",0.8,IF(D14="G",0.7,IF(D14="MG",0.6,IF(D14="F",0.45,IF(D14="MP",0.35,IF(D14="P",0.3,IF(D14="VP",0.2,"ERROR"))))))) -> 0.7 | E36: =IF(E14="VG",0.8,IF(E14="G",0.7,IF(E14="MG",0.6,IF(E14="F",0.45,IF(E14="MP",0.35,IF(E14="P",0.3,IF(E14="VP",0.2,"ERROR"))))))) -> 0.6 | F36: =IF(F14="VG",0.8,IF(F14="G",0.7,IF(F14="MG",0.6,IF(F14="F",0.45,IF(F14="MP",0.35,IF(F14="P",0.3,IF(F14="VP",0.2,"ERROR"))))))) -> 0.7 | G36: =IF(G14="VG",0.8,IF(G14="G",0.7,IF(G14="MG",0.6,IF(G14="F",0.45,IF(G14="MP",0.35,IF(G14="P",0.3,IF(G14="VP",0.2,"ERROR"))))))) -> 0.45 | H36: =IF(H14="VG",0.8,IF(H14="G",0.7,IF(H14="MG",0.6,IF(H14="F",0.45,IF(H14="MP",0.35,IF(H14="P",0.3,IF(H14="VP",0.2,"ERROR"))))))) -> 0.8 | I36: =IF(I14="VG",0.8,IF(I14="G",0.7,IF(I14="MG",0.6,IF(I14="F",0.45,IF(I14="MP",0.35,IF(I14="P",0.3,IF(I14="VP",0.2,"ERROR"))))))) -> 0.7 | J36: =IF(J14="VG",0.8,IF(J14="G",0.7,IF(J14="MG",0.6,IF(J14="F",0.45,IF(J14="MP",0.35,IF(J14="P",0.3,IF(J14="VP",0.2,"ERROR"))))))) -> 0.45 | ... AD36: =IF(AD14="VG",0.8,IF(AD14="G",0.7,IF(AD14="MG",0.6,IF(AD14="F",0.45,IF(AD14="MP",0.35,IF(AD14="P",0.3,IF(AD14="VP",0.2,"ERROR"))))))) -> 0.8 | AF36: C10 | AG36: =(C57^$C$25)*(G57^$G$25)*(K57^$K$25)*(O57^$O$25)*(S57^$S$25)*(W57^$W$25)*(AA57^$AA$25) -> 0.53170901 | AH36: =(D57^$C$25)*(H57^$G$25)*(L57^$K$25)*(P57^$O$25)*(T57^$S$25)*(X57^$W$25)*(AB57^$AA$25) -> 0.32048871 | AI36: =(E57^$C$25)*(I57^$G$25)*(M57^$K$25)*(Q57^$O$25)*(U57^$S$25)*(Y57^$W$25)*(AC57^$AA$25) -> 0.46366137 | AJ36: =(F57^$C$25)*(J57^$G$25)*(N57^$K$25)*(R57^$O$25)*(V57^$S$25)*(Z57^$W$25)*(AD57^$AA$25) -> 0.38501328
B37: C11 | C37: =IF(C15="VG",0.8,IF(C15="G",0.7,IF(C15="MG",0.6,IF(C15="F",0.45,IF(C15="MP",0.35,IF(C15="P",0.3,IF(C15="VP",0.2,"ERROR"))))))) -> 0.7 | D37: =IF(D15="VG",0.8,IF(D15="G",0.7,IF(D15="MG",0.6,IF(D15="F",0.45,IF(D15="MP",0.35,IF(D15="P",0.3,IF(D15="VP",0.2,"ERROR"))))))) -> 0.7 | E37: =IF(E15="VG",0.8,IF(E15="G",0.7,IF(E15="MG",0.6,IF(E15="F",0.45,IF(E15="MP",0.35,IF(E15="P",0.3,IF(E15="VP",0.2,"ERROR"))))))) -> 0.7 | F37: =IF(F15="VG",0.8,IF(F15="G",0.7,IF(F15="MG",0.6,IF(F15="F",0.45,IF(F15="MP",0.35,IF(F15="P",0.3,IF(F15="VP",0.2,"ERROR"))))))) -> 0.7 | G37: =IF(G15="VG",0.8,IF(G15="G",0.7,IF(G15="MG",0.6,IF(G15="F",0.45,IF(G15="MP",0.35,IF(G15="P",0.3,IF(G15="VP",0.2,"ERROR"))))))) -> 0.6 | H37: =IF(H15="VG",0.8,IF(H15="G",0.7,IF(H15="MG",0.6,IF(H15="F",0.45,IF(H15="MP",0.35,IF(H15="P",0.3,IF(H15="VP",0.2,"ERROR"))))))) -> 0.45 | I37: =IF(I15="VG",0.8,IF(I15="G",0.7,IF(I15="MG",0.6,IF(I15="F",0.45,IF(I15="MP",0.35,IF(I15="P",0.3,IF(I15="VP",0.2,"ERROR"))))))) -> 0.8 | J37: =IF(J15="VG",0.8,IF(J15="G",0.7,IF(J15="MG",0.6,IF(J15="F",0.45,IF(J15="MP",0.35,IF(J15="P",0.3,IF(J15="VP",0.2,"ERROR"))))))) -> 0.6 | ... AD37: =IF(AD15="VG",0.8,IF(AD15="G",0.7,IF(AD15="MG",0.6,IF(AD15="F",0.45,IF(AD15="MP",0.35,IF(AD15="P",0.3,IF(AD15="VP",0.2,"ERROR"))))))) -> 0.45 | AF37: C11 | AG37: =(C58^$C$25)*(G58^$G$25)*(K58^$K$25)*(O58^$O$25)*(S58^$S$25)*(W58^$W$25)*(AA58^$AA$25) -> 0.48670695 | AH37: =(D58^$C$25)*(H58^$G$25)*(L58^$K$25)*(P58^$O$25)*(T58^$S$25)*(X58^$W$25)*(AB58^$AA$25) -> 0.55587697 | AI37: =(E58^$C$25)*(I58^$G$25)*(M58^$K$25)*(Q58^$O$25)*(U58^$S$25)*(Y58^$W$25)*(AC58^$AA$25) -> 0.33491947 | AJ37: =(F58^$C$25)*(J58^$G$25)*(N58^$K$25)*(R58^$O$25)*(V58^$S$25)*(Z58^$W$25)*(AD58^$AA$25) -> 0.48670695 | BA37: Step 9. Criteria weights
B38: C12 | C38: =IF(C16="VG",0.8,IF(C16="G",0.7,IF(C16="MG",0.6,IF(C16="F",0.45,IF(C16="MP",0.35,IF(C16="P",0.3,IF(C16="VP",0.2,"ERROR"))))))) -> 0.6 | D38: =IF(D16="VG",0.8,IF(D16="G",0.7,IF(D16="MG",0.6,IF(D16="F",0.45,IF(D16="MP",0.35,IF(D16="P",0.3,IF(D16="VP",0.2,"ERROR"))))))) -> 0.8 | E38: =IF(E16="VG",0.8,IF(E16="G",0.7,IF(E16="MG",0.6,IF(E16="F",0.45,IF(E16="MP",0.35,IF(E16="P",0.3,IF(E16="VP",0.2,"ERROR"))))))) -> 0.6 | F38: =IF(F16="VG",0.8,IF(F16="G",0.7,IF(F16="MG",0.6,IF(F16="F",0.45,IF(F16="MP",0.35,IF(F16="P",0.3,IF(F16="VP",0.2,"ERROR"))))))) -> 0.8 | G38: =IF(G16="VG",0.8,IF(G16="G",0.7,IF(G16="MG",0.6,IF(G16="F",0.45,IF(G16="MP",0.35,IF(G16="P",0.3,IF(G16="VP",0.2,"ERROR"))))))) -> 0.45 | H38: =IF(H16="VG",0.8,IF(H16="G",0.7,IF(H16="MG",0.6,IF(H16="F",0.45,IF(H16="MP",0.35,IF(H16="P",0.3,IF(H16="VP",0.2,"ERROR"))))))) -> 0.35 | I38: =IF(I16="VG",0.8,IF(I16="G",0.7,IF(I16="MG",0.6,IF(I16="F",0.45,IF(I16="MP",0.35,IF(I16="P",0.3,IF(I16="VP",0.2,"ERROR"))))))) -> 0.45 | J38: =IF(J16="VG",0.8,IF(J16="G",0.7,IF(J16="MG",0.6,IF(J16="F",0.45,IF(J16="MP",0.35,IF(J16="P",0.3,IF(J16="VP",0.2,"ERROR"))))))) -> 0.7 | ... AD38: =IF(AD16="VG",0.8,IF(AD16="G",0.7,IF(AD16="MG",0.6,IF(AD16="F",0.45,IF(AD16="MP",0.35,IF(AD16="P",0.3,IF(AD16="VP",0.2,"ERROR"))))))) -> 0.7 | AF38: C12 | AG38: =(C59^$C$25)*(G59^$G$25)*(K59^$K$25)*(O59^$O$25)*(S59^$S$25)*(W59^$W$25)*(AA59^$AA$25) -> 0.41416023 | AH38: =(D59^$C$25)*(H59^$G$25)*(L59^$K$25)*(P59^$O$25)*(T59^$S$25)*(X59^$W$25)*(AB59^$AA$25) -> 0.42567065 | AI38: =(E59^$C$25)*(I59^$G$25)*(M59^$K$25)*(Q59^$O$25)*(U59^$S$25)*(Y59^$W$25)*(AC59^$AA$25) -> 0.42631775 | AJ38: =(F59^$C$25)*(J59^$G$25)*(N59^$K$25)*(R59^$O$25)*(V59^$S$25)*(Z59^$W$25)*(AD59^$AA$25) -> 0.42997778 | BA38: Sum | BB38: =SUM(BB32:BB35) -> 0.13269209 | BC38: =SUM(BC32:BC35) -> 0.25886567 | BD38: =SUM(BD32:BD35) -> 0.16577524 | BE38: =SUM(BE32:BE35) -> 0.11924039 | BF38: =SUM(BF32:BF35) -> 0.1676121 | BG38: =SUM(BG32:BG35) -> 0.10628109 | BH38: =SUM(BH32:BH35) -> 0.057944172 | BI38: =SUM(BI32:BI35) -> 0.079292693 | ... BS38: =SUM(BS32:BS35) -> 0.075114298
B39: C13 | C39: =IF(C17="VG",0.8,IF(C17="G",0.7,IF(C17="MG",0.6,IF(C17="F",0.45,IF(C17="MP",0.35,IF(C17="P",0.3,IF(C17="VP",0.2,"ERROR"))))))) -> 0.6 | D39: =IF(D17="VG",0.8,IF(D17="G",0.7,IF(D17="MG",0.6,IF(D17="F",0.45,IF(D17="MP",0.35,IF(D17="P",0.3,IF(D17="VP",0.2,"ERROR"))))))) -> 0.7 | E39: =IF(E17="VG",0.8,IF(E17="G",0.7,IF(E17="MG",0.6,IF(E17="F",0.45,IF(E17="MP",0.35,IF(E17="P",0.3,IF(E17="VP",0.2,"ERROR"))))))) -> 0.6 | F39: =IF(F17="VG",0.8,IF(F17="G",0.7,IF(F17="MG",0.6,IF(F17="F",0.45,IF(F17="MP",0.35,IF(F17="P",0.3,IF(F17="VP",0.2,"ERROR"))))))) -> 0.6 | G39: =IF(G17="VG",0.8,IF(G17="G",0.7,IF(G17="MG",0.6,IF(G17="F",0.45,IF(G17="MP",0.35,IF(G17="P",0.3,IF(G17="VP",0.2,"ERROR"))))))) -> 0.45 | H39: =IF(H17="VG",0.8,IF(H17="G",0.7,IF(H17="MG",0.6,IF(H17="F",0.45,IF(H17="MP",0.35,IF(H17="P",0.3,IF(H17="VP",0.2,"ERROR"))))))) -> 0.3 | I39: =IF(I17="VG",0.8,IF(I17="G",0.7,IF(I17="MG",0.6,IF(I17="F",0.45,IF(I17="MP",0.35,IF(I17="P",0.3,IF(I17="VP",0.2,"ERROR"))))))) -> 0.7 | J39: =IF(J17="VG",0.8,IF(J17="G",0.7,IF(J17="MG",0.6,IF(J17="F",0.45,IF(J17="MP",0.35,IF(J17="P",0.3,IF(J17="VP",0.2,"ERROR"))))))) -> 0.6 | ... AD39: =IF(AD17="VG",0.8,IF(AD17="G",0.7,IF(AD17="MG",0.6,IF(AD17="F",0.45,IF(AD17="MP",0.35,IF(AD17="P",0.3,IF(AD17="VP",0.2,"ERROR"))))))) -> 0.7 | AF39: C13 | AG39: =(C60^$C$25)*(G60^$G$25)*(K60^$K$25)*(O60^$O$25)*(S60^$S$25)*(W60^$W$25)*(AA60^$AA$25) -> 0.49428945 | AH39: =(D60^$C$25)*(H60^$G$25)*(L60^$K$25)*(P60^$O$25)*(T60^$S$25)*(X60^$W$25)*(AB60^$AA$25) -> 0.40005469 | AI39: =(E60^$C$25)*(I60^$G$25)*(M60^$K$25)*(Q60^$O$25)*(U60^$S$25)*(Y60^$W$25)*(AC60^$AA$25) -> 0.47133687 | AJ39: =(F60^$C$25)*(J60^$G$25)*(N60^$K$25)*(R60^$O$25)*(V60^$S$25)*(Z60^$W$25)*(AD60^$AA$25) -> 0.51491778
